Workbook
Name Frente: 'Página 1 Impressão'!$B$1:$CO$139
Name Verso: Ficha!$B$142:$CO$282
Name Frente: Ficha!$B$1:$CO$140
Name Frente: 'Página 2 Impressão'!$B$1:$CO$1
Name Verso: #REF!
Name Grimorio: 'Grimório'!$A$1:$CP$137
Name Verso: 'Página 2 Impressão'!$B$3:$CO$142

Sheet Ficha
E2: O REINO | V2: Nome | AA2: Baldo | BB2: Jogador | BH2: Kauê | BV2: Data de Criação | CF2: 2014
V4: Altura | AA4: 1,36 m | AF4: Peso | AJ4: 91 kg | AO4: Raça | AS4: Anão | AZ4: Reino | BE4: Nog Faldur | BO4: Idade | BS4: 27 | BV4: Pontos p/ Gastar | CF4: =Indice!$H$3-$CH$275 -> 42.5
V6: Aparência | AC6: Olhos laranjas, cabelo marrom trançado
E8: PLANILHA DE PERSONAGEM
E10: ST | L10: =rounddown(switch($B$12,-80,1,-70,2,-60,3,-50,4,-40,5,-30,6,-20,7,-15,8,-10,9,0,10,10,11,20,12,30,13,45,14,60,15,80,16,$B$12/25+13),0)+2 -> 17 | T10: P. Fadiga | Z10: =$L$10+2 -> 19 | AC10: / | AD10: =$L$10+2 -> 19 | BL10: Perícias
B12: 60
T13: P. Mana | Z13: =$L$10+2+$AD$96 -> 197 | AC13: / | AD13: =$L$10+2+$AD$96 -> 197 | BK13: Custo | BO13: Nome | CC13: Dificuldade | CJ13: NH
BL14: 2 | BO14: Trovador | CD14: M/M | CJ14: =SWITCH(CD14,"F/F",SWITCH(BL14,0.5,$L$16-1,1,$L$16,2,$L$16+1,4,$L$16+2,$L$16+BL14/8+2),"F/M",SWITCH(BL14,0.5,$L$16-2,1,$L$16-1,2,$L$16,4,$L$16+1,$L$16+BL14/8+1),"F/D",SWITCH(BL14,0.5,$L$16-3,1,$L$16-2,2,$L$16-1,4,$L$16,$L$16+BL14/8),"M/F",SWITCH(BL14,0.5,$L$22,1,$L$22+1,$L$22+BL14),"M/M",SWITCH(BL14,0.5,$L$22-1,1,$L$22,$L$22+BL14-1),"M/D",SWITCH(BL14,0.5,$L$22-2,1,$L$22-1,$L$22+BL14-2),"M/MD",SWITCH(BL14,0.5,$L$22-3,1,$L$22-2,2,$L$22-1,$L$22+BL14/2-2),"F/F HT",SWITCH(BL14,0.5,$L$28-1,1,$L$28,2,$L$28+1,4,$L$28+2,$L$28+BL14/8+2),"F/M HT",SWITCH(BL14,0.5,$L$28-2,1,$L$28-1,2,$L$28,4,$L$28+1,$L$28+BL14/8+1),"F/D HT",SWITCH(BL14,0.5,$L$28-3,1,$L$28-2,2,$L$28-1,4,$L$28,$L$28+BL14/8),"M/F HT",SWITCH(BL14,0.5,$L$28-1,1,$L$28,$L$28+BL14/2),"M/M HT",SWITCH(BL14,0.5,$L$28-2,1,$L$28-1,$L$28+BL14/2-1),"M/D HT",SWITCH(BL14,0.5,$L$28-3,1,$L$28-2,$L$28+BL14/2-2),"M/MD HT",SWITCH(BL14,0.5,$L$28-4,1,$L$28-3,2,$L$28-2,$L$28+BL14/4-2),"")+(SWITCH(CM14,"A",4,"B",$BF$64,"C","","D",3,"E",1,"G",4,"H",1,"L",0,"M",$AD$92,"S",$BF$66,"T",$AD$132,"U",3,"V",2,"R",1,"")+SWITCH(CN14,"A",4,"B",$BF$64,"C","","D",3,"E",1,"G",4,"H",1,"L",0,"M",$AD$92,"S",$BF$66,"T",$AD$132,"U",3,"V",2,"R",1,"")+SWITCH(CO14,"A",4,"B",$BF$64,"C","","D",3,"E",1,"G",4,"H",1,"L",0,"M",$AD$92,"S",$BF$66,"T",$AD$132,"U",3,"V",2,"R",1,"")) -> 21
E16: DX | L16: =rounddown(switch($B$18,-80,1,-70,2,-60,3,-50,4,-40,5,-30,6,-20,7,-15,8,-10,9,0,10,10,11,20,12,30,13,45,14,60,15,80,16,$B$18/25+13),0) -> 16 | T16: Vontade | Z16: =$L$22 -> 20 | BL16: 1 | BO16: Caligrafia | CD16: F/M | CJ16: =SWITCH(CD16,"F/F",SWITCH(BL16,0.5,$L$16-1,1,$L$16,2,$L$16+1,4,$L$16+2,$L$16+BL16/8+2),"F/M",SWITCH(BL16,0.5,$L$16-2,1,$L$16-1,2,$L$16,4,$L$16+1,$L$16+BL16/8+1),"F/D",SWITCH(BL16,0.5,$L$16-3,1,$L$16-2,2,$L$16-1,4,$L$16,$L$16+BL16/8),"M/F",SWITCH(BL16,0.5,$L$22,1,$L$22+1,$L$22+BL16),"M/M",SWITCH(BL16,0.5,$L$22-1,1,$L$22,$L$22+BL16-1),"M/D",SWITCH(BL16,0.5,$L$22-2,1,$L$22-1,$L$22+BL16-2),"M/MD",SWITCH(BL16,0.5,$L$22-3,1,$L$22-2,2,$L$22-1,$L$22+BL16/2-2),"F/F HT",SWITCH(BL16,0.5,$L$28-1,1,$L$28,2,$L$28+1,4,$L$28+2,$L$28+BL16/8+2),"F/M HT",SWITCH(BL16,0.5,$L$28-2,1,$L$28-1,2,$L$28,4,$L$28+1,$L$28+BL16/8+1),"F/D HT",SWITCH(BL16,0.5,$L$28-3,1,$L$28-2,2,$L$28-1,4,$L$28,$L$28+BL16/8),"M/F HT",SWITCH(BL16,0.5,$L$28-1,1,$L$28,$L$28+BL16/2),"M/M HT",SWITCH(BL16,0.5,$L$28-2,1,$L$28-1,$L$28+BL16/2-1),"M/D HT",SWITCH(BL16,0.5,$L$28-3,1,$L$28-2,$L$28+BL16/2-2),"M/MD HT",SWITCH(BL16,0.5,$L$28-4,1,$L$28-3,2,$L$28-2,$L$28+BL16/4-2),"")+(SWITCH(CM16,"A",4,"B",$BF$64,"C","","D",3,"E",1,"G",4,"H",1,"L",0,"M",$AD$92,"S",$BF$66,"T",$AD$132,"U",3,"V",2,"R",1,"")+SWITCH(CN16,"A",4,"B",$BF$64,"C","","D",3,"E",1,"G",4,"H",1,"L",0,"M",$AD$92,"S",$BF$66,"T",$AD$132,"U",3,"V",2,"R",1,"")+SWITCH(CO16,"A",4,"B",$BF$64,"C","","D",3,"E",1,"G",4,"H",1,"L",0,"M",$AD$92,"S",$BF$66,"T",$AD$132,"U",3,"V",2,"R",1,"")) -> 15
B18: 80 | BL18: 0.5 | BO18: Dança | CD18: F/M | CJ18: =SWITCH(CD18,"F/F",SWITCH(BL18,0.5,$L$16-1,1,$L$16,2,$L$16+1,4,$L$16+2,$L$16+BL18/8+2),"F/M",SWITCH(BL18,0.5,$L$16-2,1,$L$16-1,2,$L$16,4,$L$16+1,$L$16+BL18/8+1),"F/D",SWITCH(BL18,0.5,$L$16-3,1,$L$16-2,2,$L$16-1,4,$L$16,$L$16+BL18/8),"M/F",SWITCH(BL18,0.5,$L$22,1,$L$22+1,$L$22+BL18),"M/M",SWITCH(BL18,0.5,$L$22-1,1,$L$22,$L$22+BL18-1),"M/D",SWITCH(BL18,0.5,$L$22-2,1,$L$22-1,$L$22+BL18-2),"M/MD",SWITCH(BL18,0.5,$L$22-3,1,$L$22-2,2,$L$22-1,$L$22+BL18/2-2),"F/F HT",SWITCH(BL18,0.5,$L$28-1,1,$L$28,2,$L$28+1,4,$L$28+2,$L$28+BL18/8+2),"F/M HT",SWITCH(BL18,0.5,$L$28-2,1,$L$28-1,2,$L$28,4,$L$28+1,$L$28+BL18/8+1),"F/D HT",SWITCH(BL18,0.5,$L$28-3,1,$L$28-2,2,$L$28-1,4,$L$28,$L$28+BL18/8),"M/F HT",SWITCH(BL18,0.5,$L$28-1,1,$L$28,$L$28+BL18/2),"M/M HT",SWITCH(BL18,0.5,$L$28-2,1,$L$28-1,$L$28+BL18/2-1),"M/D HT",SWITCH(BL18,0.5,$L$28-3,1,$L$28-2,$L$28+BL18/2-2),"M/MD HT",SWITCH(BL18,0.5,$L$28-4,1,$L$28-3,2,$L$28-2,$L$28+BL18/4-2),"")+(SWITCH(CM18,"A",4,"B",$BF$64,"C","","D",3,"E",1,"G",4,"H",1,"L",0,"M",$AD$92,"S",$BF$66,"T",$AD$132,"U",3,"V",2,"R",1,"")+SWITCH(CN18,"A",4,"B",$BF$64,"C","","D",3,"E",1,"G",4,"H",1,"L",0,"M",$AD$92,"S",$BF$66,"T",$AD$132,"U",3,"V",2,"R",1,"")+SWITCH(CO18,"A",4,"B",$BF$64,"C","","D",3,"E",1,"G",4,"H",1,"L",0,"M",$AD$92,"S",$BF$66,"T",$AD$132,"U",3,"V",2,"R",1,"")) -> 14
BL20: 0.5 | BO20: Escultura | CD20: F/M | CJ20: =SWITCH(CD20,"F/F",SWITCH(BL20,0.5,$L$16-1,1,$L$16,2,$L$16+1,4,$L$16+2,$L$16+BL20/8+2),"F/M",SWITCH(BL20,0.5,$L$16-2,1,$L$16-1,2,$L$16,4,$L$16+1,$L$16+BL20/8+1),"F/D",SWITCH(BL20,0.5,$L$16-3,1,$L$16-2,2,$L$16-1,4,$L$16,$L$16+BL20/8),"M/F",SWITCH(BL20,0.5,$L$22,1,$L$22+1,$L$22+BL20),"M/M",SWITCH(BL20,0.5,$L$22-1,1,$L$22,$L$22+BL20-1),"M/D",SWITCH(BL20,0.5,$L$22-2,1,$L$22-1,$L$22+BL20-2),"M/MD",SWITCH(BL20,0.5,$L$22-3,1,$L$22-2,2,$L$22-1,$L$22+BL20/2-2),"F/F HT",SWITCH(BL20,0.5,$L$28-1,1,$L$28,2,$L$28+1,4,$L$28+2,$L$28+BL20/8+2),"F/M HT",SWITCH(BL20,0.5,$L$28-2,1,$L$28-1,2,$L$28,4,$L$28+1,$L$28+BL20/8+1),"F/D HT",SWITCH(BL20,0.5,$L$28-3,1,$L$28-2,2,$L$28-1,4,$L$28,$L$28+BL20/8),"M/F HT",SWITCH(BL20,0.5,$L$28-1,1,$L$28,$L$28+BL20/2),"M/M HT",SWITCH(BL20,0.5,$L$28-2,1,$L$28-1,$L$28+BL20/2-1),"M/D HT",SWITCH(BL20,0.5,$L$28-3,1,$L$28-2,$L$28+BL20/2-2),"M/MD HT",SWITCH(BL20,0.5,$L$28-4,1,$L$28-3,2,$L$28-2,$L$28+BL20/4-2),"")+(SWITCH(CM20,"A",4,"B",$BF$64,"C","","D",3,"E",1,"G",4,"H",1,"L",0,"M",$AD$92,"S",$BF$66,"T",$AD$132,"U",3,"V",2,"R",1,"")+SWITCH(CN20,"A",4,"B",$BF$64,"C","","D",3,"E",1,"G",4,"H",1,"L",0,"M",$AD$92,"S",$BF$66,"T",$AD$132,"U",3,"V",2,"R",1,"")+SWITCH(CO20,"A",4,"B",$BF$64,"C","","D",3,"E",1,"G",4,"H",1,"L",0,"M",$AD$92,"S",$BF$66,"T",$AD$132,"U",3,"V",2,"R",1,"")) -> 17 | CM20: D
E22: IQ | L22: =rounddown(switch($B$24,-80,1,-70,2,-60,3,-50,4,-40,5,-30,6,-20,7,-15,8,-10,9,0,10,10,11,20,12,30,13,45,14,60,15,80,16,$B$24/25+13),0) -> 20 | T22: Percepção | Z22: =L22 -> 20 | BL22: 2 | BO22: Controle da Respiração | CD22: M/MD | CJ22: =SWITCH(CD22,"F/F",SWITCH(BL22,0.5,$L$16-1,1,$L$16,2,$L$16+1,4,$L$16+2,$L$16+BL22/8+2),"F/M",SWITCH(BL22,0.5,$L$16-2,1,$L$16-1,2,$L$16,4,$L$16+1,$L$16+BL22/8+1),"F/D",SWITCH(BL22,0.5,$L$16-3,1,$L$16-2,2,$L$16-1,4,$L$16,$L$16+BL22/8),"M/F",SWITCH(BL22,0.5,$L$22,1,$L$22+1,$L$22+BL22),"M/M",SWITCH(BL22,0.5,$L$22-1,1,$L$22,$L$22+BL22-1),"M/D",SWITCH(BL22,0.5,$L$22-2,1,$L$22-1,$L$22+BL22-2),"M/MD",SWITCH(BL22,0.5,$L$22-3,1,$L$22-2,2,$L$22-1,$L$22+BL22/2-2),"F/F HT",SWITCH(BL22,0.5,$L$28-1,1,$L$28,2,$L$28+1,4,$L$28+2,$L$28+BL22/8+2),"F/M HT",SWITCH(BL22,0.5,$L$28-2,1,$L$28-1,2,$L$28,4,$L$28+1,$L$28+BL22/8+1),"F/D HT",SWITCH(BL22,0.5,$L$28-3,1,$L$28-2,2,$L$28-1,4,$L$28,$L$28+BL22/8),"M/F HT",SWITCH(BL22,0.5,$L$28-1,1,$L$28,$L$28+BL22/2),"M/M HT",SWITCH(BL22,0.5,$L$28-2,1,$L$28-1,$L$28+BL22/2-1),"M/D HT",SWITCH(BL22,0.5,$L$28-3,1,$L$28-2,$L$28+BL22/2-2),"M/MD HT",SWITCH(BL22,0.5,$L$28-4,1,$L$28-3,2,$L$28-2,$L$28+BL22/4-2),"")+(SWITCH(CM22,"A",4,"B",$BF$64,"C","","D",3,"E",1,"G",4,"H",1,"L",0,"M",$AD$92,"S",$BF$66,"T",$AD$132,"U",3,"V",2,"R",1,"")+SWITCH(CN22,"A",4,"B",$BF$64,"C","","D",3,"E",1,"G",4,"H",1,"L",0,"M",$AD$92,"S",$BF$66,"T",$AD$132,"U",3,"V",2,"R",1,"")+SWITCH(CO22,"A",4,"B",$BF$64,"C","","D",3,"E",1,"G",4,"H",1,"L",0,"M",$AD$92,"S",$BF$66,"T",$AD$132,"U",3,"V",2,"R",1,"")) -> 19
B24: 175 | BL24: 8 | BO24: Corrida | CD24: F/D HT | CJ24: =SWITCH(CD24,"F/F",SWITCH(BL24,0.5,$L$16-1,1,$L$16,2,$L$16+1,4,$L$16+2,$L$16+BL24/8+2),"F/M",SWITCH(BL24,0.5,$L$16-2,1,$L$16-1,2,$L$16,4,$L$16+1,$L$16+BL24/8+1),"F/D",SWITCH(BL24,0.5,$L$16-3,1,$L$16-2,2,$L$16-1,4,$L$16,$L$16+BL24/8),"M/F",SWITCH(BL24,0.5,$L$22,1,$L$22+1,$L$22+BL24),"M/M",SWITCH(BL24,0.5,$L$22-1,1,$L$22,$L$22+BL24-1),"M/D",SWITCH(BL24,0.5,$L$22-2,1,$L$22-1,$L$22+BL24-2),"M/MD",SWITCH(BL24,0.5,$L$22-3,1,$L$22-2,2,$L$22-1,$L$22+BL24/2-2),"F/F HT",SWITCH(BL24,0.5,$L$28-1,1,$L$28,2,$L$28+1,4,$L$28+2,$L$28+BL24/8+2),"F/M HT",SWITCH(BL24,0.5,$L$28-2,1,$L$28-1,2,$L$28,4,$L$28+1,$L$28+BL24/8+1),"F/D HT",SWITCH(BL24,0.5,$L$28-3,1,$L$28-2,2,$L$28-1,4,$L$28,$L$28+BL24/8),"M/F HT",SWITCH(BL24,0.5,$L$28-1,1,$L$28,$L$28+BL24/2),"M/M HT",SWITCH(BL24,0.5,$L$28-2,1,$L$28-1,$L$28+BL24/2-1),"M/D HT",SWITCH(BL24,0.5,$L$28-3,1,$L$28-2,$L$28+BL24/2-2),"M/MD HT",SWITCH(BL24,0.5,$L$28-4,1,$L$28-3,2,$L$28-2,$L$28+BL24/4-2),"")+(SWITCH(CM24,"A",4,"B",$BF$64,"C","","D",3,"E",1,"G",4,"H",1,"L",0,"M",$AD$92,"S",$BF$66,"T",$AD$132,"U",3,"V",2,"R",1,"")+SWITCH(CN24,"A",4,"B",$BF$64,"C","","D",3,"E",1,"G",4,"H",1,"L",0,"M",$AD$92,"S",$BF$66,"T",$AD$132,"U",3,"V",2,"R",1,"")+SWITCH(CO24,"A",4,"B",$BF$64,"C","","D",3,"E",1,"G",4,"H",1,"L",0,"M",$AD$92,"S",$BF$66,"T",$AD$132,"U",3,"V",2,"R",1,"")) -> 19
BL26: 24 | BO26: Machado/Maça | CD26: F/M | CJ26: =SWITCH(CD26,"F/F",SWITCH(BL26,0.5,$L$16-1,1,$L$16,2,$L$16+1,4,$L$16+2,$L$16+BL26/8+2),"F/M",SWITCH(BL26+2,0.5,$L$16-2,1,$L$16-1,2,$L$16,4,$L$16+1,$L$16+BL26/8+1),"F/D",SWITCH(BL26,0.5,$L$16-3,1,$L$16-2,2,$L$16-1,4,$L$16,$L$16+BL26/8),"M/F",SWITCH(BL26,0.5,$L$22,1,$L$22+1,$L$22+BL26),"M/M",SWITCH(BL26,0.5,$L$22-1,1,$L$22,$L$22+BL26-1),"M/D",SWITCH(BL26,0.5,$L$22-2,1,$L$22-1,$L$22+BL26-2),"M/MD",SWITCH(BL26,0.5,$L$22-3,1,$L$22-2,2,$L$22-1,$L$22+BL26-2),"F/F HT",SWITCH(BL26,0.5,$L$28-1,1,$L$28,2,$L$28+1,4,$L$28+2,$L$28+BL26/8+2),"F/M HT",SWITCH(BL26,0.5,$L$28-2,1,$L$28-1,2,$L$28,4,$L$28+1,$L$28+BL26/8+1),"F/D HT",SWITCH(BL26,0.5,$L$28-3,1,$L$28-2,2,$L$28-1,4,$L$28,$L$28+BL26/8),"M/F HT",SWITCH(BL26,0.5,$L$28-1,1,$L$28,$L$28+BL26/2),"M/M HT",SWITCH(BL26,0.5,$L$28-2,1,$L$28-1,$L$28+BL26/2-1),"M/D HT",SWITCH(BL26,0.5,$L$28-3,1,$L$28-2,$L$28+BL26/2-2),"M/MD HT",SWITCH(BL26,0.5,$L$28-4,1,$L$28-3,2,$L$28-2,$L$28+BL26/4-2),"")+(SWITCH(CM26,"A",4,"B",$BF$64,"C","","D",3,"E",1,"G",4,"H",1,"L",0,"M",$AD$92,"S",$BF$66,"T",$AD$132,"U",3,"V",2,"R",1,"")+SWITCH(CN26,"A",4,"B",$BF$64,"C","","D",3,"E",1,"G",4,"H",1,"L",0,"M",$AD$92,"S",$BF$66,"T",$AD$132,"U",3,"V",2,"R",1,"")+SWITCH(CO26,"A",4,"B",$BF$64,"C","","D",3,"E",1,"G",4,"H",1,"L",0,"M",$AD$92,"S",$BF$66,"T",$AD$132,"U",3,"V",2,"R",1,"")) -> 20
E28: HT | L28: =rounddown(switch($B$30,-80,1,-70,2,-60,3,-50,4,-40,5,-30,6,-20,7,-15,8,-10,9,0,10,10,11,20,12,30,13,45,14,60,15,80,16,$B$30/25+13),0) -> 18 | T28: P. Vida | Z28: =L28 -> 18 | AC28: / | AD28: =L28 -> 18 | BL28: 2 | BO28: Briga | CD28: F/F | CJ28: =SWITCH(CD28,"F/F",SWITCH(BL28,0.5,$L$16-1,1,$L$16,2,$L$16+1,4,$L$16+2,$L$16+BL28/8+2),"F/M",SWITCH(BL28,0.5,$L$16-2,1,$L$16-1,2,$L$16,4,$L$16+1,$L$16+BL28/8+1),"F/D",SWITCH(BL28,0.5,$L$16-3,1,$L$16-2,2,$L$16-1,4,$L$16,$L$16+BL28/8),"M/F",SWITCH(BL28,0.5,$L$22,1,$L$22+1,$L$22+BL28),"M/M",SWITCH(BL28,0.5,$L$22-1,1,$L$22,$L$22+BL28-1),"M/D",SWITCH(BL28,0.5,$L$22-2,1,$L$22-1,$L$22+BL28-2),"M/MD",SWITCH(BL28,0.5,$L$22-3,1,$L$22-2,2,$L$22-1,$L$22+BL28/2-2),"F/F HT",SWITCH(BL28,0.5,$L$28-1,1,$L$28,2,$L$28+1,4,$L$28+2,$L$28+BL28/8+2),"F/M HT",SWITCH(BL28,0.5,$L$28-2,1,$L$28-1,2,$L$28,4,$L$28+1,$L$28+BL28/8+1),"F/D HT",SWITCH(BL28,0.5,$L$28-3,1,$L$28-2,2,$L$28-1,4,$L$28,$L$28+BL28/8),"M/F HT",SWITCH(BL28,0.5,$L$28-1,1,$L$28,$L$28+BL28/2),"M/M HT",SWITCH(BL28,0.5,$L$28-2,1,$L$28-1,$L$28+BL28/2-1),"M/D HT",SWITCH(BL28,0.5,$L$28-3,1,$L$28-2,$L$28+BL28/2-2),"M/MD HT",SWITCH(BL28,0.5,$L$28-4,1,$L$28-3,2,$L$28-2,$L$28+BL28/4-2),"")+(SWITCH(CM28,"A",4,"B",$BF$64,"C","","D",3,"E",1,"G",4,"H",1,"L",0,"M",$AD$92,"S",$BF$66,"T",$AD$132,"U",3,"V",2,"R",1,"")+SWITCH(CN28,"A",4,"B",$BF$64,"C","","D",3,"E",1,"G",4,"H",1,"L",0,"M",$AD$92,"S",$BF$66,"T",$AD$132,"U",3,"V",2,"R",1,"")+SWITCH(CO28,"A",4,"B",$BF$64,"C","","D",3,"E",1,"G",4,"H",1,"L",0,"M",$AD$92,"S",$BF$66,"T",$AD$132,"U",3,"V",2,"R",1,"")) -> 17
B30: 125 | BL30: 4 | BO30: Escudo | CD30: F/F | CJ30: =SWITCH(CD30,"F/F",SWITCH(BL30,0.5,$L$16-1,1,$L$16,2,$L$16+1,4,$L$16+2,$L$16+BL30/8+2),"F/M",SWITCH(BL30,0.5,$L$16-2,1,$L$16-1,2,$L$16,4,$L$16+1,$L$16+BL30/8+1),"F/D",SWITCH(BL30,0.5,$L$16-3,1,$L$16-2,2,$L$16-1,4,$L$16,$L$16+BL30/8),"M/F",SWITCH(BL30,0.5,$L$22,1,$L$22+1,$L$22+BL30),"M/M",SWITCH(BL30,0.5,$L$22-1,1,$L$22,$L$22+BL30-1),"M/D",SWITCH(BL30,0.5,$L$22-2,1,$L$22-1,$L$22+BL30-2),"M/MD",SWITCH(BL30,0.5,$L$22-3,1,$L$22-2,2,$L$22-1,$L$22+BL30/2-2),"F/F HT",SWITCH(BL30,0.5,$L$28-1,1,$L$28,2,$L$28+1,4,$L$28+2,$L$28+BL30/8+2),"F/M HT",SWITCH(BL30,0.5,$L$28-2,1,$L$28-1,2,$L$28,4,$L$28+1,$L$28+BL30/8+1),"F/D HT",SWITCH(BL30,0.5,$L$28-3,1,$L$28-2,2,$L$28-1,4,$L$28,$L$28+BL30/8),"M/F HT",SWITCH(BL30,0.5,$L$28-1,1,$L$28,$L$28+BL30/2),"M/M HT",SWITCH(BL30,0.5,$L$28-2,1,$L$28-1,$L$28+BL30/2-1),"M/D HT",SWITCH(BL30,0.5,$L$28-3,1,$L$28-2,$L$28+BL30/2-2),"M/MD HT",SWITCH(BL30,0.5,$L$28-4,1,$L$28-3,2,$L$28-2,$L$28+BL30/4-2),"")+(SWITCH(CM30,"A",4,"B",$BF$64,"C","","D",3,"E",1,"G",4,"H",1,"L",0,"M",$AD$92,"S",$BF$66,"T",$AD$132,"U",3,"V",2,"R",1,"")+SWITCH(CN30,"A",4,"B",$BF$64,"C","","D",3,"E",1,"G",4,"H",1,"L",0,"M",$AD$92,"S",$BF$66,"T",$AD$132,"U",3,"V",2,"R",1,"")+SWITCH(CO30,"A",4,"B",$BF$64,"C","","D",3,"E",1,"G",4,"H",1,"L",0,"M",$AD$92,"S",$BF$66,"T",$AD$132,"U",3,"V",2,"R",1,"")) -> 18
BL32: 2 | BO32: Armeiro 4 | CD32: M/M | CJ32: =SWITCH(CD32,"F/F",SWITCH(BL32,0.5,$L$16-1,1,$L$16,2,$L$16+1,4,$L$16+2,$L$16+BL32/8+2),"F/M",SWITCH(BL32,0.5,$L$16-2,1,$L$16-1,2,$L$16,4,$L$16+1,$L$16+BL32/8+1),"F/D",SWITCH(BL32,0.5,$L$16-3,1,$L$16-2,2,$L$16-1,4,$L$16,$L$16+BL32/8),"M/F",SWITCH(BL32,0.5,$L$22,1,$L$22+1,$L$22+BL32),"M/M",SWITCH(BL32,0.5,$L$22-1,1,$L$22,$L$22+BL32-1),"M/D",SWITCH(BL32,0.5,$L$22-2,1,$L$22-1,$L$22+BL32-2),"M/MD",SWITCH(BL32,0.5,$L$22-3,1,$L$22-2,2,$L$22-1,$L$22+BL32/2-2),"F/F HT",SWITCH(BL32,0.5,$L$28-1,1,$L$28,2,$L$28+1,4,$L$28+2,$L$28+BL32/8+2),"F/M HT",SWITCH(BL32,0.5,$L$28-2,1,$L$28-1,2,$L$28,4,$L$28+1,$L$28+BL32/8+1),"F/D HT",SWITCH(BL32,0.5,$L$28-3,1,$L$28-2,2,$L$28-1,4,$L$28,$L$28+BL32/8),"M/F HT",SWITCH(BL32,0.5,$L$28-1,1,$L$28,$L$28+BL32/2),"M/M HT",SWITCH(BL32,0.5,$L$28-2,1,$L$28-1,$L$28+BL32/2-1),"M/D HT",SWITCH(BL32,0.5,$L$28-3,1,$L$28-2,$L$28+BL32/2-2),"M/MD HT",SWITCH(BL32,0.5,$L$28-4,1,$L$28-3,2,$L$28-2,$L$28+BL32/4-2),"")+(SWITCH(CM32,"A",4,"B",$BF$64,"C","","D",3,"E",1,"G",4,"H",1,"L",0,"M",$AD$92,"S",$BF$66,"T",$AD$132,"U",3,"V",2,"R",1,"")+SWITCH(CN32,"A",4,"B",$BF$64,"C","","D",3,"E",1,"G",4,"H",1,"L",0,"M",$AD$92,"S",$BF$66,"T",$AD$132,"U",3,"V",2,"R",1,"")+SWITCH(CO32,"A",4,"B",$BF$64,"C","","D",3,"E",1,"G",4,"H",1,"L",0,"M",$AD$92,"S",$BF$66,"T",$AD$132,"U",3,"V",2,"R",1,"")) -> 24 | CM32: D
E34: Base de Carga | O34: Dano GDP | X34: Dano BAL | BL34: 2 | BO34: Ferreiro 4 | CD34: M/M | CJ34: =SWITCH(CD34,"F/F",SWITCH(BL34,0.5,$L$16-1,1,$L$16,2,$L$16+1,4,$L$16+2,$L$16+BL34/8+2),"F/M",SWITCH(BL34,0.5,$L$16-2,1,$L$16-1,2,$L$16,4,$L$16+1,$L$16+BL34/8+1),"F/D",SWITCH(BL34,0.5,$L$16-3,1,$L$16-2,2,$L$16-1,4,$L$16,$L$16+BL34/8),"M/F",SWITCH(BL34,0.5,$L$22,1,$L$22+1,$L$22+BL34),"M/M",SWITCH(BL34,0.5,$L$22-1,1,$L$22,$L$22+BL34-1),"M/D",SWITCH(BL34,0.5,$L$22-2,1,$L$22-1,$L$22+BL34-2),"M/MD",SWITCH(BL34,0.5,$L$22-3,1,$L$22-2,2,$L$22-1,$L$22+BL34/2-2),"F/F HT",SWITCH(BL34,0.5,$L$28-1,1,$L$28,2,$L$28+1,4,$L$28+2,$L$28+BL34/8+2),"F/M HT",SWITCH(BL34,0.5,$L$28-2,1,$L$28-1,2,$L$28,4,$L$28+1,$L$28+BL34/8+1),"F/D HT",SWITCH(BL34,0.5,$L$28-3,1,$L$28-2,2,$L$28-1,4,$L$28,$L$28+BL34/8),"M/F HT",SWITCH(BL34,0.5,$L$28-1,1,$L$28,$L$28+BL34/2),"M/M HT",SWITCH(BL34,0.5,$L$28-2,1,$L$28-1,$L$28+BL34/2-1),"M/D HT",SWITCH(BL34,0.5,$L$28-3,1,$L$28-2,$L$28+BL34/2-2),"M/MD HT",SWITCH(BL34,0.5,$L$28-4,1,$L$28-3,2,$L$28-2,$L$28+BL34/4-2),"")+(SWITCH(CM34,"A",4,"B",$BF$64,"C","","D",3,"E",1,"G",4,"H",1,"L",0,"M",$AD$92,"S",$BF$66,"T",$AD$132,"U",3,"V",2,"R",1,"")+SWITCH(CN34,"A",4,"B",$BF$64,"C","","D",3,"E",1,"G",4,"H",1,"L",0,"M",$AD$92,"S",$BF$66,"T",$AD$132,"U",3,"V",2,"R",1,"")+SWITCH(CO34,"A",4,"B",$BF$64,"C","","D",3,"E",1,"G",4,"H",1,"L",0,"M",$AD$92,"S",$BF$66,"T",$AD$132,"U",3,"V",2,"R",1,"")) -> 24 | CM34: D
E36: =L10 -> 17 | O36: =SWITCH($L$10,1,,2,,3,,4,,5,"1D",6,"1D",7,"1D",8,"1D",9,"1D",10,"1D",11,"1D",12,"1D",13,"1D",14,"1D",15,"1D",16,"1D",17,"1D",18,"1D",19,"2D",20,"2D",21,"2D",22,"2D",23,"2D",24,"2D",25,"2D",26,"2D",27,"2D",28,"2D",29,"3D",30,"3D","Olo") -> 1D | T36: =SWITCH($L$10,1,0,2,0,3,0,4,0,5,-5,6,-4,7,-3,8,-3,9,-2,10,-2,11,-1,12,-1,13,,14,,15,+1,16,+1,17,+2,18,+2,19,-1,20,-1,21,,22,,23,+1,24,+1,25,+2,26,+2,27,+3,28,+3,29,-1,30,-1,"co") -> 2 | X36: =SWITCH($L$10,1,,2,,3,,4,,5,"1D",6,"1D",7,"1D",8,"1D",9,"1D",10,"1D",11,"1D",12,"1D",13,"2D",14,"2D",15,"2D",16,"2D",17,"3D",18,"3D",19,"3D",20,"3D",21,"4D",22,"4D",23,"4D",24,"4D",25,"5D",26,"5D",27,"5D",28,"5D",29,"5D",30,"5D","Olo") -> 3D | AC36: =SWITCH($L$10,1,0,2,0,3,0,4,0,5,-5,6,-4,7,-3,8,-2,9,-1,10,,11,+1,12,+2,13,-1,14,,15,+1,16,+2,17,-1,18,,19,+1,20,+2,21,-1,22,,23,+1,24,+2,25,-1,26,,27,+1,28,+1,29,2,30,+2,"co") -> -1 | BL36: 0.5 | BO36: Carpintaria | CD36: M/F | CJ36: =SWITCH(CD36,"F/F",SWITCH(BL36,0.5,$L$16-1,1,$L$16,2,$L$16+1,4,$L$16+2,$L$16+BL36/8+2),"F/M",SWITCH(BL36,0.5,$L$16-2,1,$L$16-1,2,$L$16,4,$L$16+1,$L$16+BL36/8+1),"F/D",SWITCH(BL36,0.5,$L$16-3,1,$L$16-2,2,$L$16-1,4,$L$16,$L$16+BL36/8),"M/F",SWITCH(BL36,0.5,$L$22,1,$L$22+1,$L$22+BL36),"M/M",SWITCH(BL36,0.5,$L$22-1,1,$L$22,$L$22+BL36-1),"M/D",SWITCH(BL36,0.5,$L$22-2,1,$L$22-1,$L$22+BL36-2),"M/MD",SWITCH(BL36,0.5,$L$22-3,1,$L$22-2,2,$L$22-1,$L$22+BL36/2-2),"F/F HT",SWITCH(BL36,0.5,$L$28-1,1,$L$28,2,$L$28+1,4,$L$28+2,$L$28+BL36/8+2),"F/M HT",SWITCH(BL36,0.5,$L$28-2,1,$L$28-1,2,$L$28,4,$L$28+1,$L$28+BL36/8+1),"F/D HT",SWITCH(BL36,0.5,$L$28-3,1,$L$28-2,2,$L$28-1,4,$L$28,$L$28+BL36/8),"M/F HT",SWITCH(BL36,0.5,$L$28-1,1,$L$28,$L$28+BL36/2),"M/M HT",SWITCH(BL36,0.5,$L$28-2,1,$L$28-1,$L$28+BL36/2-1),"M/D HT",SWITCH(BL36,0.5,$L$28-3,1,$L$28-2,$L$28+BL36/2-2),"M/MD HT",SWITCH(BL36,0.5,$L$28-4,1,$L$28-3,2,$L$28-2,$L$28+BL36/4-2),"")+(SWITCH(CM36,"A",4,"B",$BF$64,"C","","D",3,"E",1,"G",4,"H",1,"L",0,"M",$AD$92,"S",$BF$66,"T",$AD$132,"U",3,"V",2,"R",1,"")+SWITCH(CN36,"A",4,"B",$BF$64,"C","","D",3,"E",1,"G",4,"H",1,"L",0,"M",$AD$92,"S",$BF$66,"T",$AD$132,"U",3,"V",2,"R",1,"")+SWITCH(CO36,"A",4,"B",$BF$64,"C","","D",3,"E",1,"G",4,"H",1,"L",0,"M",$AD$92,"S",$BF$66,"T",$AD$132,"U",3,"V",2,"R",1,"")) -> 23 | CM36: D
BL38: 2 | BO38: Culinaria | CD38: M/F | CJ38: =SWITCH(CD38,"F/F",SWITCH(BL38,0.5,$L$16-1,1,$L$16,2,$L$16+1,4,$L$16+2,$L$16+BL38/8+2),"F/M",SWITCH(BL38,0.5,$L$16-2,1,$L$16-1,2,$L$16,4,$L$16+1,$L$16+BL38/8+1),"F/D",SWITCH(BL38,0.5,$L$16-3,1,$L$16-2,2,$L$16-1,4,$L$16,$L$16+BL38/8),"M/F",SWITCH(BL38,0.5,$L$22,1,$L$22+1,$L$22+BL38),"M/M",SWITCH(BL38,0.5,$L$22-1,1,$L$22,$L$22+BL38-1),"M/D",SWITCH(BL38,0.5,$L$22-2,1,$L$22-1,$L$22+BL38-2),"M/MD",SWITCH(BL38,0.5,$L$22-3,1,$L$22-2,2,$L$22-1,$L$22+BL38/2-2),"F/F HT",SWITCH(BL38,0.5,$L$28-1,1,$L$28,2,$L$28+1,4,$L$28+2,$L$28+BL38/8+2),"F/M HT",SWITCH(BL38,0.5,$L$28-2,1,$L$28-1,2,$L$28,4,$L$28+1,$L$28+BL38/8+1),"F/D HT",SWITCH(BL38,0.5,$L$28-3,1,$L$28-2,2,$L$28-1,4,$L$28,$L$28+BL38/8),"M/F HT",SWITCH(BL38,0.5,$L$28-1,1,$L$28,$L$28+BL38/2),"M/M HT",SWITCH(BL38,0.5,$L$28-2,1,$L$28-1,$L$28+BL38/2-1),"M/D HT",SWITCH(BL38,0.5,$L$28-3,1,$L$28-2,$L$28+BL38/2-2),"M/MD HT",SWITCH(BL38,0.5,$L$28-4,1,$L$28-3,2,$L$28-2,$L$28+BL38/4-2),"")+(SWITCH(CM38,"A",4,"B",$BF$64,"C","","D",3,"E",1,"G",4,"H",1,"L",0,"M",$AD$92,"S",$BF$66,"T",$AD$132,"U",3,"V",2,"R",1,"")+SWITCH(CN38,"A",4,"B",$BF$64,"C","","D",3,"E",1,"G",4,"H",1,"L",0,"M",$AD$92,"S",$BF$66,"T",$AD$132,"U",3,"V",2,"R",1,"")+SWITCH(CO38,"A",4,"B",$BF$64,"C","","D",3,"E",1,"G",4,"H",1,"L",0,"M",$AD$92,"S",$BF$66,"T",$AD$132,"U",3,"V",2,"R",1,"")) -> 25 | CM38: D
BL40: 1 | BO40: Joalheiro 4 | CD40: M/D | CJ40: =SWITCH(CD40,"F/F",SWITCH(BL40,0.5,$L$16-1,1,$L$16,2,$L$16+1,4,$L$16+2,$L$16+BL40/8+2),"F/M",SWITCH(BL40,0.5,$L$16-2,1,$L$16-1,2,$L$16,4,$L$16+1,$L$16+BL40/8+1),"F/D",SWITCH(BL40,0.5,$L$16-3,1,$L$16-2,2,$L$16-1,4,$L$16,$L$16+BL40/8),"M/F",SWITCH(BL40,0.5,$L$22,1,$L$22+1,$L$22+BL40),"M/M",SWITCH(BL40,0.5,$L$22-1,1,$L$22,$L$22+BL40-1),"M/D",SWITCH(BL40,0.5,$L$22-2,1,$L$22-1,$L$22+BL40-2),"M/MD",SWITCH(BL40,0.5,$L$22-3,1,$L$22-2,2,$L$22-1,$L$22+BL40/2-2),"F/F HT",SWITCH(BL40,0.5,$L$28-1,1,$L$28,2,$L$28+1,4,$L$28+2,$L$28+BL40/8+2),"F/M HT",SWITCH(BL40,0.5,$L$28-2,1,$L$28-1,2,$L$28,4,$L$28+1,$L$28+BL40/8+1),"F/D HT",SWITCH(BL40,0.5,$L$28-3,1,$L$28-2,2,$L$28-1,4,$L$28,$L$28+BL40/8),"M/F HT",SWITCH(BL40,0.5,$L$28-1,1,$L$28,$L$28+BL40/2),"M/M HT",SWITCH(BL40,0.5,$L$28-2,1,$L$28-1,$L$28+BL40/2-1),"M/D HT",SWITCH(BL40,0.5,$L$28-3,1,$L$28-2,$L$28+BL40/2-2),"M/MD HT",SWITCH(BL40,0.5,$L$28-4,1,$L$28-3,2,$L$28-2,$L$28+BL40/4-2),"")+(SWITCH(CM40,"A",4,"B",$BF$64,"C","","D",3,"E",1,"G",4,"H",1,"L",0,"M",$AD$92,"S",$BF$66,"T",$AD$132,"U",3,"V",2,"R",1,"")+SWITCH(CN40,"A",4,"B",$BF$64,"C","","D",3,"E",1,"G",4,"H",1,"L",0,"M",$AD$92,"S",$BF$66,"T",$AD$132,"U",3,"V",2,"R",1,"")+SWITCH(CO40,"A",4,"B",$BF$64,"C","","D",3,"E",1,"G",4,"H",1,"L",0,"M",$AD$92,"S",$BF$66,"T",$AD$132,"U",3,"V",2,"R",1,"")) -> 22 | CM40: D
E41: Velocidade Básica | S41: Deslocamento Básico
BL42: 2 | BO42: Trabalhos em Couro | CD42: M/F | CJ42: =SWITCH(CD42,"F/F",SWITCH(BL42,0.5,$L$16-1,1,$L$16,2,$L$16+1,4,$L$16+2,$L$16+BL42/8+2),"F/M",SWITCH(BL42,0.5,$L$16-2,1,$L$16-1,2,$L$16,4,$L$16+1,$L$16+BL42/8+1),"F/D",SWITCH(BL42,0.5,$L$16-3,1,$L$16-2,2,$L$16-1,4,$L$16,$L$16+BL42/8),"M/F",SWITCH(BL42,0.5,$L$22,1,$L$22+1,$L$22+BL42),"M/M",SWITCH(BL42,0.5,$L$22-1,1,$L$22,$L$22+BL42-1),"M/D",SWITCH(BL42,0.5,$L$22-2,1,$L$22-1,$L$22+BL42-2),"M/MD",SWITCH(BL42,0.5,$L$22-3,1,$L$22-2,2,$L$22-1,$L$22+BL42/2-2),"F/F HT",SWITCH(BL42,0.5,$L$28-1,1,$L$28,2,$L$28+1,4,$L$28+2,$L$28+BL42/8+2),"F/M HT",SWITCH(BL42,0.5,$L$28-2,1,$L$28-1,2,$L$28,4,$L$28+1,$L$28+BL42/8+1),"F/D HT",SWITCH(BL42,0.5,$L$28-3,1,$L$28-2,2,$L$28-1,4,$L$28,$L$28+BL42/8),"M/F HT",SWITCH(BL42,0.5,$L$28-1,1,$L$28,$L$28+BL42/2),"M/M HT",SWITCH(BL42,0.5,$L$28-2,1,$L$28-1,$L$28+BL42/2-1),"M/D HT",SWITCH(BL42,0.5,$L$28-3,1,$L$28-2,$L$28+BL42/2-2),"M/MD HT",SWITCH(BL42,0.5,$L$28-4,1,$L$28-3,2,$L$28-2,$L$28+BL42/4-2),"")+(SWITCH(CM42,"A",4,"B",$BF$64,"C","","D",3,"E",1,"G",4,"H",1,"L",0,"M",$AD$92,"S",$BF$66,"T",$AD$132,"U",3,"V",2,"R",1,"")+SWITCH(CN42,"A",4,"B",$BF$64,"C","","D",3,"E",1,"G",4,"H",1,"L",0,"M",$AD$92,"S",$BF$66,"T",$AD$132,"U",3,"V",2,"R",1,"")+SWITCH(CO42,"A",4,"B",$BF$64,"C","","D",3,"E",1,"G",4,"H",1,"L",0,"M",$AD$92,"S",$BF$66,"T",$AD$132,"U",3,"V",2,"R",1,"")) -> 25 | CM42: D | CP42: $
E43: =((L16+L28)/4)+($CJ$22/8)+BG122 -> 10.875 | S43: =ROUNDDOWN(E43,0)-1 -> 9
BL44: 0.5 | BO44: Mecanica 4 (Engrenagens) | CD44: M/F | CJ44: =SWITCH(CD44,"F/F",SWITCH(BL44,0.5,$L$16-1,1,$L$16,2,$L$16+1,4,$L$16+2,$L$16+BL44/8+2),"F/M",SWITCH(BL44,0.5,$L$16-2,1,$L$16-1,2,$L$16,4,$L$16+1,$L$16+BL44/8+1),"F/D",SWITCH(BL44,0.5,$L$16-3,1,$L$16-2,2,$L$16-1,4,$L$16,$L$16+BL44/8),"M/F",SWITCH(BL44,0.5,$L$22,1,$L$22+1,$L$22+BL44),"M/M",SWITCH(BL44,0.5,$L$22-1,1,$L$22,$L$22+BL44-1),"M/D",SWITCH(BL44,0.5,$L$22-2,1,$L$22-1,$L$22+BL44-2),"M/MD",SWITCH(BL44,0.5,$L$22-3,1,$L$22-2,2,$L$22-1,$L$22+BL44/2-2),"F/F HT",SWITCH(BL44,0.5,$L$28-1,1,$L$28,2,$L$28+1,4,$L$28+2,$L$28+BL44/8+2),"F/M HT",SWITCH(BL44,0.5,$L$28-2,1,$L$28-1,2,$L$28,4,$L$28+1,$L$28+BL44/8+1),"F/D HT",SWITCH(BL44,0.5,$L$28-3,1,$L$28-2,2,$L$28-1,4,$L$28,$L$28+BL44/8),"M/F HT",SWITCH(BL44,0.5,$L$28-1,1,$L$28,$L$28+BL44/2),"M/M HT",SWITCH(BL44,0.5,$L$28-2,1,$L$28-1,$L$28+BL44/2-1),"M/D HT",SWITCH(BL44,0.5,$L$28-3,1,$L$28-2,$L$28+BL44/2-2),"M/MD HT",SWITCH(BL44,0.5,$L$28-4,1,$L$28-3,2,$L$28-2,$L$28+BL44/4-2),"")+(SWITCH(CM44,"A",4,"B",$BF$64,"C","","D",3,"E",1,"G",4,"H",1,"L",0,"M",$AD$92,"S",$BF$66,"T",$AD$132,"U",3,"V",2,"R",1,"")+SWITCH(CN44,"A",4,"B",$BF$64,"C","","D",3,"E",1,"G",4,"H",1,"L",0,"M",$AD$92,"S",$BF$66,"T",$AD$132,"U",3,"V",2,"R",1,"")+SWITCH(CO44,"A",4,"B",$BF$64,"C","","D",3,"E",1,"G",4,"H",1,"L",0,"M",$AD$92,"S",$BF$66,"T",$AD$132,"U",3,"V",2,"R",1,"")) -> 23 | CM44: D | CP44: $
BL46: 0.5 | BO46: Ceramica | CD46: M/M | CJ46: =SWITCH(CD46,"F/F",SWITCH(BL46,0.5,$L$16-1,1,$L$16,2,$L$16+1,4,$L$16+2,$L$16+BL46/8+2),"F/M",SWITCH(BL46,0.5,$L$16-2,1,$L$16-1,2,$L$16,4,$L$16+1,$L$16+BL46/8+1),"F/D",SWITCH(BL46,0.5,$L$16-3,1,$L$16-2,2,$L$16-1,4,$L$16,$L$16+BL46/8),"M/F",SWITCH(BL46,0.5,$L$22,1,$L$22+1,$L$22+BL46),"M/M",SWITCH(BL46,0.5,$L$22-1,1,$L$22,$L$22+BL46-1),"M/D",SWITCH(BL46,0.5,$L$22-2,1,$L$22-1,$L$22+BL46-2),"M/MD",SWITCH(BL46,0.5,$L$22-3,1,$L$22-2,2,$L$22-1,$L$22+BL46/2-2),"F/F HT",SWITCH(BL46,0.5,$L$28-1,1,$L$28,2,$L$28+1,4,$L$28+2,$L$28+BL46/8+2),"F/M HT",SWITCH(BL46,0.5,$L$28-2,1,$L$28-1,2,$L$28,4,$L$28+1,$L$28+BL46/8+1),"F/D HT",SWITCH(BL46,0.5,$L$28-3,1,$L$28-2,2,$L$28-1,4,$L$28,$L$28+BL46/8),"M/F HT",SWITCH(BL46,0.5,$L$28-1,1,$L$28,$L$28+BL46/2),"M/M HT",SWITCH(BL46,0.5,$L$28-2,1,$L$28-1,$L$28+BL46/2-1),"M/D HT",SWITCH(BL46,0.5,$L$28-3,1,$L$28-2,$L$28+BL46/2-2),"M/MD HT",SWITCH(BL46,0.5,$L$28-4,1,$L$28-3,2,$L$28-2,$L$28+BL46/4-2),"")+(SWITCH(CM46,"A",4,"B",$BF$64,"C","","D",3,"E",1,"G",4,"H",1,"L",0,"M",$AD$92,"S",$BF$66,"T",$AD$132,"U",3,"V",2,"R",1,"")+SWITCH(CN46,"A",4,"B",$BF$64,"C","","D",3,"E",1,"G",4,"H",1,"L",0,"M",$AD$92,"S",$BF$66,"T",$AD$132,"U",3,"V",2,"R",1,"")+SWITCH(CO46,"A",4,"B",$BF$64,"C","","D",3,"E",1,"G",4,"H",1,"L",0,"M",$AD$92,"S",$BF$66,"T",$AD$132,"U",3,"V",2,"R",1,"")) -> 22 | CM46: D | CP46: $
E48: Nível de Carga | R48: Deslocamento | Z48: Esquiva | BL48: 0.5 | BO48: Marcenaria | CD48: F/M | CJ48: =SWITCH(CD48,"F/F",SWITCH(BL48,0.5,$L$16-1,1,$L$16,2,$L$16+1,4,$L$16+2,$L$16+BL48/8+2),"F/M",SWITCH(BL48,0.5,$L$16-2,1,$L$16-1,2,$L$16,4,$L$16+1,$L$16+BL48/8+1),"F/D",SWITCH(BL48,0.5,$L$16-3,1,$L$16-2,2,$L$16-1,4,$L$16,$L$16+BL48/8),"M/F",SWITCH(BL48,0.5,$L$22,1,$L$22+1,$L$22+BL48),"M/M",SWITCH(BL48,0.5,$L$22-1,1,$L$22,$L$22+BL48-1),"M/D",SWITCH(BL48,0.5,$L$22-2,1,$L$22-1,$L$22+BL48-2),"M/MD",SWITCH(BL48,0.5,$L$22-3,1,$L$22-2,2,$L$22-1,$L$22+BL48/2-2),"F/F HT",SWITCH(BL48,0.5,$L$28-1,1,$L$28,2,$L$28+1,4,$L$28+2,$L$28+BL48/8+2),"F/M HT",SWITCH(BL48,0.5,$L$28-2,1,$L$28-1,2,$L$28,4,$L$28+1,$L$28+BL48/8+1),"F/D HT",SWITCH(BL48,0.5,$L$28-3,1,$L$28-2,2,$L$28-1,4,$L$28,$L$28+BL48/8),"M/F HT",SWITCH(BL48,0.5,$L$28-1,1,$L$28,$L$28+BL48/2),"M/M HT",SWITCH(BL48,0.5,$L$28-2,1,$L$28-1,$L$28+BL48/2-1),"M/D HT",SWITCH(BL48,0.5,$L$28-3,1,$L$28-2,$L$28+BL48/2-2),"M/MD HT",SWITCH(BL48,0.5,$L$28-4,1,$L$28-3,2,$L$28-2,$L$28+BL48/4-2),"")+(SWITCH(CM48,"A",4,"B",$BF$64,"C","","D",3,"E",1,"G",4,"H",1,"L",0,"M",$AD$92,"S",$BF$66,"T",$AD$132,"U",3,"V",2,"R",1,"")+SWITCH(CN48,"A",4,"B",$BF$64,"C","","D",3,"E",1,"G",4,"H",1,"L",0,"M",$AD$92,"S",$BF$66,"T",$AD$132,"U",3,"V",2,"R",1,"")+SWITCH(CO48,"A",4,"B",$BF$64,"C","","D",3,"E",1,"G",4,"H",1,"L",0,"M",$AD$92,"S",$BF$66,"T",$AD$132,"U",3,"V",2,"R",1,"")) -> 17 | CM48: D
E50: Nenhuma (0) = BC | N50: =$E$36 -> 17 | R50: DB | V50: =$S$43 -> 9 | Z50: Esquiva | AE50: =$E$63 -> #REF! | BL50: 0.5 | BO50: Destilaria | CD50: M/M | CJ50: =SWITCH(CD50,"F/F",SWITCH(BL50,0.5,$L$16-1,1,$L$16,2,$L$16+1,4,$L$16+2,$L$16+BL50/8+2),"F/M",SWITCH(BL50,0.5,$L$16-2,1,$L$16-1,2,$L$16,4,$L$16+1,$L$16+BL50/8+1),"F/D",SWITCH(BL50,0.5,$L$16-3,1,$L$16-2,2,$L$16-1,4,$L$16,$L$16+BL50/8),"M/F",SWITCH(BL50,0.5,$L$22,1,$L$22+1,$L$22+BL50),"M/M",SWITCH(BL50,0.5,$L$22-1,1,$L$22,$L$22+BL50-1),"M/D",SWITCH(BL50,0.5,$L$22-2,1,$L$22-1,$L$22+BL50-2),"M/MD",SWITCH(BL50,0.5,$L$22-3,1,$L$22-2,2,$L$22-1,$L$22+BL50/2-2),"F/F HT",SWITCH(BL50,0.5,$L$28-1,1,$L$28,2,$L$28+1,4,$L$28+2,$L$28+BL50/8+2),"F/M HT",SWITCH(BL50,0.5,$L$28-2,1,$L$28-1,2,$L$28,4,$L$28+1,$L$28+BL50/8+1),"F/D HT",SWITCH(BL50,0.5,$L$28-3,1,$L$28-2,2,$L$28-1,4,$L$28,$L$28+BL50/8),"M/F HT",SWITCH(BL50,0.5,$L$28-1,1,$L$28,$L$28+BL50/2),"M/M HT",SWITCH(BL50,0.5,$L$28-2,1,$L$28-1,$L$28+BL50/2-1),"M/D HT",SWITCH(BL50,0.5,$L$28-3,1,$L$28-2,$L$28+BL50/2-2),"M/MD HT",SWITCH(BL50,0.5,$L$28-4,1,$L$28-3,2,$L$28-2,$L$28+BL50/4-2),"")+(SWITCH(CM50,"A",4,"B",$BF$64,"C","","D",3,"E",1,"G",4,"H",1,"L",0,"M",$AD$92,"S",$BF$66,"T",$AD$132,"U",3,"V",2,"R",1,"")+SWITCH(CN50,"A",4,"B",$BF$64,"C","","D",3,"E",1,"G",4,"H",1,"L",0,"M",$AD$92,"S",$BF$66,"T",$AD$132,"U",3,"V",2,"R",1,"")+SWITCH(CO50,"A",4,"B",$BF$64,"C","","D",3,"E",1,"G",4,"H",1,"L",0,"M",$AD$92,"S",$BF$66,"T",$AD$132,"U",3,"V",2,"R",1,"")) -> 22 | CM50: D
E52: Leve (1) = 2,5xBC | N52: =$E$36*2.5 -> 42.5 | R52: DB-1 | V52: =$S$43-1 -> 8 | Z52: Esquiva-1 | AE52: =$E$63-1 -> #REF! | BL52: 0.5 | BO52: Alvenaria | CD52: F/F | CJ52: =SWITCH(CD52,"F/F",SWITCH(BL52,0.5,$L$16-1,1,$L$16,2,$L$16+1,4,$L$16+2,$L$16+BL52/8+2),"F/M",SWITCH(BL52,0.5,$L$16-2,1,$L$16-1,2,$L$16,4,$L$16+1,$L$16+BL52/8+1),"F/D",SWITCH(BL52,0.5,$L$16-3,1,$L$16-2,2,$L$16-1,4,$L$16,$L$16+BL52/8),"M/F",SWITCH(BL52,0.5,$L$22,1,$L$22+1,$L$22+BL52),"M/M",SWITCH(BL52,0.5,$L$22-1,1,$L$22,$L$22+BL52-1),"M/D",SWITCH(BL52,0.5,$L$22-2,1,$L$22-1,$L$22+BL52-2),"M/MD",SWITCH(BL52,0.5,$L$22-3,1,$L$22-2,2,$L$22-1,$L$22+BL52/2-2),"F/F HT",SWITCH(BL52,0.5,$L$28-1,1,$L$28,2,$L$28+1,4,$L$28+2,$L$28+BL52/8+2),"F/M HT",SWITCH(BL52,0.5,$L$28-2,1,$L$28-1,2,$L$28,4,$L$28+1,$L$28+BL52/8+1),"F/D HT",SWITCH(BL52,0.5,$L$28-3,1,$L$28-2,2,$L$28-1,4,$L$28,$L$28+BL52/8),"M/F HT",SWITCH(BL52,0.5,$L$28-1,1,$L$28,$L$28+BL52/2),"M/M HT",SWITCH(BL52,0.5,$L$28-2,1,$L$28-1,$L$28+BL52/2-1),"M/D HT",SWITCH(BL52,0.5,$L$28-3,1,$L$28-2,$L$28+BL52/2-2),"M/MD HT",SWITCH(BL52,0.5,$L$28-4,1,$L$28-3,2,$L$28-2,$L$28+BL52/4-2),"")+(SWITCH(CM52,"A",4,"B",$BF$64,"C","","D",3,"E",1,"G",4,"H",1,"L",0,"M",$AD$92,"S",$BF$66,"T",$AD$132,"U",3,"V",2,"R",1,"")+SWITCH(CN52,"A",4,"B",$BF$64,"C","","D",3,"E",1,"G",4,"H",1,"L",0,"M",$AD$92,"S",$BF$66,"T",$AD$132,"U",3,"V",2,"R",1,"")+SWITCH(CO52,"A",4,"B",$BF$64,"C","","D",3,"E",1,"G",4,"H",1,"L",0,"M",$AD$92,"S",$BF$66,"T",$AD$132,"U",3,"V",2,"R",1,"")) -> 18 | CM52: D
E54: Média (2) = 5xBC | N54: =$E$36*5 -> 85 | R54: DB-2 | V54: =$S$43-2 -> 7 | Z54: Esquiva-2 | AE54: =$E$63-2 -> #REF! | BL54: 0.5 | BO54: Comum | CD54: M/M | CJ54: =SWITCH(CD54,"F/F",SWITCH(BL54,0.5,$L$16-1,1,$L$16,2,$L$16+1,4,$L$16+2,$L$16+BL54/8+2),"F/M",SWITCH(BL54,0.5,$L$16-2,1,$L$16-1,2,$L$16,4,$L$16+1,$L$16+BL54/8+1),"F/D",SWITCH(BL54,0.5,$L$16-3,1,$L$16-2,2,$L$16-1,4,$L$16,$L$16+BL54/8),"M/F",SWITCH(BL54,0.5,$L$22,1,$L$22+1,$L$22+BL54),"M/M",SWITCH(BL54,0.5,$L$22-1,1,$L$22,$L$22+BL54-1),"M/D",SWITCH(BL54,0.5,$L$22-2,1,$L$22-1,$L$22+BL54-2),"M/MD",SWITCH(BL54,0.5,$L$22-3,1,$L$22-2,2,$L$22-1,$L$22+BL54/2-2),"F/F HT",SWITCH(BL54,0.5,$L$28-1,1,$L$28,2,$L$28+1,4,$L$28+2,$L$28+BL54/8+2),"F/M HT",SWITCH(BL54,0.5,$L$28-2,1,$L$28-1,2,$L$28,4,$L$28+1,$L$28+BL54/8+1),"F/D HT",SWITCH(BL54,0.5,$L$28-3,1,$L$28-2,2,$L$28-1,4,$L$28,$L$28+BL54/8),"M/F HT",SWITCH(BL54,0.5,$L$28-1,1,$L$28,$L$28+BL54/2),"M/M HT",SWITCH(BL54,0.5,$L$28-2,1,$L$28-1,$L$28+BL54/2-1),"M/D HT",SWITCH(BL54,0.5,$L$28-3,1,$L$28-2,$L$28+BL54/2-2),"M/MD HT",SWITCH(BL54,0.5,$L$28-4,1,$L$28-3,2,$L$28-2,$L$28+BL54/4-2),"")+(SWITCH(CM54,"A",4,"B",$BF$64,"C","","D",3,"E",1,"G",4,"H",1,"L",0,"M",$AD$92,"S",$BF$66,"T",$AD$132,"U",3,"V",2,"R",1,"")+SWITCH(CN54,"A",4,"B",$BF$64,"C","","D",3,"E",1,"G",4,"H",1,"L",0,"M",$AD$92,"S",$BF$66,"T",$AD$132,"U",3,"V",2,"R",1,"")+SWITCH(CO54,"A",4,"B",$BF$64,"C","","D",3,"E",1,"G",4,"H",1,"L",0,"M",$AD$92,"S",$BF$66,"T",$AD$132,"U",3,"V",2,"R",1,"")) -> 19
E56: Pesada (3) = 10xBC | N56: =$E$36*10 -> 170 | R56: DB-3 | V56: =$S$43-3 -> 6 | Z56: Esquiva-3 | AE56: =$E$63-3 -> #REF! | BL56: 0.5 | BO56: Primeiros Socorros | CD56: M/F | CJ56: =SWITCH(CD56,"F/F",SWITCH(BL56,0.5,$L$16-1,1,$L$16,2,$L$16+1,4,$L$16+2,$L$16+BL56/8+2),"F/M",SWITCH(BL56,0.5,$L$16-2,1,$L$16-1,2,$L$16,4,$L$16+1,$L$16+BL56/8+1),"F/D",SWITCH(BL56,0.5,$L$16-3,1,$L$16-2,2,$L$16-1,4,$L$16,$L$16+BL56/8),"M/F",SWITCH(BL56,0.5,$L$22,1,$L$22+1,$L$22+BL56),"M/M",SWITCH(BL56,0.5,$L$22-1,1,$L$22,$L$22+BL56-1),"M/D",SWITCH(BL56,0.5,$L$22-2,1,$L$22-1,$L$22+BL56-2),"M/MD",SWITCH(BL56,0.5,$L$22-3,1,$L$22-2,2,$L$22-1,$L$22+BL56/2-2),"F/F HT",SWITCH(BL56,0.5,$L$28-1,1,$L$28,2,$L$28+1,4,$L$28+2,$L$28+BL56/8+2),"F/M HT",SWITCH(BL56,0.5,$L$28-2,1,$L$28-1,2,$L$28,4,$L$28+1,$L$28+BL56/8+1),"F/D HT",SWITCH(BL56,0.5,$L$28-3,1,$L$28-2,2,$L$28-1,4,$L$28,$L$28+BL56/8),"M/F HT",SWITCH(BL56,0.5,$L$28-1,1,$L$28,$L$28+BL56/2),"M/M HT",SWITCH(BL56,0.5,$L$28-2,1,$L$28-1,$L$28+BL56/2-1),"M/D HT",SWITCH(BL56,0.5,$L$28-3,1,$L$28-2,$L$28+BL56/2-2),"M/MD HT",SWITCH(BL56,0.5,$L$28-4,1,$L$28-3,2,$L$28-2,$L$28+BL56/4-2),"")+(SWITCH(CM56,"A",4,"B",$BF$64,"C","","D",3,"E",1,"G",4,"H",1,"L",0,"M",$AD$92,"S",$BF$66,"T",$AD$132,"U",3,"V",2,"R",1,"")+SWITCH(CN56,"A",4,"B",$BF$64,"C","","D",3,"E",1,"G",4,"H",1,"L",0,"M",$AD$92,"S",$BF$66,"T",$AD$132,"U",3,"V",2,"R",1,"")+SWITCH(CO56,"A",4,"B",$BF$64,"C","","D",3,"E",1,"G",4,"H",1,"L",0,"M",$AD$92,"S",$BF$66,"T",$AD$132,"U",3,"V",2,"R",1,"")) -> 20
E58: M.Pes (4) = 15xBC | N58: =$E$36*15 -> 255 | R58: DB-4 | V58: =$S$43-4 -> 5 | Z58: Esquiva-4 | AE58: =$E$63-4 -> #REF! | BL58: 0.5 | BO58: Naturalista | CD58: M/D | CJ58: =SWITCH(CD58,"F/F",SWITCH(BL58,0.5,$L$16-1,1,$L$16,2,$L$16+1,4,$L$16+2,$L$16+BL58/8+2),"F/M",SWITCH(BL58,0.5,$L$16-2,1,$L$16-1,2,$L$16,4,$L$16+1,$L$16+BL58/8+1),"F/D",SWITCH(BL58,0.5,$L$16-3,1,$L$16-2,2,$L$16-1,4,$L$16,$L$16+BL58/8),"M/F",SWITCH(BL58,0.5,$L$22,1,$L$22+1,$L$22+BL58),"M/M",SWITCH(BL58,0.5,$L$22-1,1,$L$22,$L$22+BL58-1),"M/D",SWITCH(BL58,0.5,$L$22-2,1,$L$22-1,$L$22+BL58-2),"M/MD",SWITCH(BL58,0.5,$L$22-3,1,$L$22-2,2,$L$22-1,$L$22+BL58/2-2),"F/F HT",SWITCH(BL58,0.5,$L$28-1,1,$L$28,2,$L$28+1,4,$L$28+2,$L$28+BL58/8+2),"F/M HT",SWITCH(BL58,0.5,$L$28-2,1,$L$28-1,2,$L$28,4,$L$28+1,$L$28+BL58/8+1),"F/D HT",SWITCH(BL58,0.5,$L$28-3,1,$L$28-2,2,$L$28-1,4,$L$28,$L$28+BL58/8),"M/F HT",SWITCH(BL58,0.5,$L$28-1,1,$L$28,$L$28+BL58/2),"M/M HT",SWITCH(BL58,0.5,$L$28-2,1,$L$28-1,$L$28+BL58/2-1),"M/D HT",SWITCH(BL58,0.5,$L$28-3,1,$L$28-2,$L$28+BL58/2-2),"M/MD HT",SWITCH(BL58,0.5,$L$28-4,1,$L$28-3,2,$L$28-2,$L$28+BL58/4-2),"")+(SWITCH(CM58,"A",4,"B",$BF$64,"C","","D",3,"E",1,"G",4,"H",1,"L",0,"M",$AD$92,"S",$BF$66,"T",$AD$132,"U",3,"V",2,"R",1,"")+SWITCH(CN58,"A",4,"B",$BF$64,"C","","D",3,"E",1,"G",4,"H",1,"L",0,"M",$AD$92,"S",$BF$66,"T",$AD$132,"U",3,"V",2,"R",1,"")+SWITCH(CO58,"A",4,"B",$BF$64,"C","","D",3,"E",1,"G",4,"H",1,"L",0,"M",$AD$92,"S",$BF$66,"T",$AD$132,"U",3,"V",2,"R",1,"")) -> 18
BL60: 0.5 | BO60: Geologia 4 | CD60: M/D | CJ60: =SWITCH(CD60,"F/F",SWITCH(BL60,0.5,$L$16-1,1,$L$16,2,$L$16+1,4,$L$16+2,$L$16+BL60/8+2),"F/M",SWITCH(BL60,0.5,$L$16-2,1,$L$16-1,2,$L$16,4,$L$16+1,$L$16+BL60/8+1),"F/D",SWITCH(BL60,0.5,$L$16-3,1,$L$16-2,2,$L$16-1,4,$L$16,$L$16+BL60/8),"M/F",SWITCH(BL60,0.5,$L$22,1,$L$22+1,$L$22+BL60),"M/M",SWITCH(BL60,0.5,$L$22-1,1,$L$22,$L$22+BL60-1),"M/D",SWITCH(BL60,0.5,$L$22-2,1,$L$22-1,$L$22+BL60-2),"M/MD",SWITCH(BL60,0.5,$L$22-3,1,$L$22-2,2,$L$22-1,$L$22+BL60/2-2),"F/F HT",SWITCH(BL60,0.5,$L$28-1,1,$L$28,2,$L$28+1,4,$L$28+2,$L$28+BL60/8+2),"F/M HT",SWITCH(BL60,0.5,$L$28-2,1,$L$28-1,2,$L$28,4,$L$28+1,$L$28+BL60/8+1),"F/D HT",SWITCH(BL60,0.5,$L$28-3,1,$L$28-2,2,$L$28-1,4,$L$28,$L$28+BL60/8),"M/F HT",SWITCH(BL60,0.5,$L$28-1,1,$L$28,$L$28+BL60/2),"M/M HT",SWITCH(BL60,0.5,$L$28-2,1,$L$28-1,$L$28+BL60/2-1),"M/D HT",SWITCH(BL60,0.5,$L$28-3,1,$L$28-2,$L$28+BL60/2-2),"M/MD HT",SWITCH(BL60,0.5,$L$28-4,1,$L$28-3,2,$L$28-2,$L$28+BL60/4-2),"")+(SWITCH(CM60,"A",4,"B",$BF$64,"C","","D",3,"E",1,"G",4,"H",1,"L",0,"M",$AD$92,"S",$BF$66,"T",$AD$132,"U",3,"V",2,"R",1,"")+SWITCH(CN60,"A",4,"B",$BF$64,"C","","D",3,"E",1,"G",4,"H",1,"L",0,"M",$AD$92,"S",$BF$66,"T",$AD$132,"U",3,"V",2,"R",1,"")+SWITCH(CO60,"A",4,"B",$BF$64,"C","","D",3,"E",1,"G",4,"H",1,"L",0,"M",$AD$92,"S",$BF$66,"T",$AD$132,"U",3,"V",2,"R",1,"")) -> 18
E61: Esquiva | O61: Aparar | X61: Bloqueio | AI61: Modificadores de Reação
BL62: 0.5 | BO62: História | CD62: M/D | CJ62: =SWITCH(CD62,"F/F",SWITCH(BL62,0.5,$L$16-1,1,$L$16,2,$L$16+1,4,$L$16+2,$L$16+BL62/8+2),"F/M",SWITCH(BL62,0.5,$L$16-2,1,$L$16-1,2,$L$16,4,$L$16+1,$L$16+BL62/8+1),"F/D",SWITCH(BL62,0.5,$L$16-3,1,$L$16-2,2,$L$16-1,4,$L$16,$L$16+BL62/8),"M/F",SWITCH(BL62,0.5,$L$22,1,$L$22+1,$L$22+BL62),"M/M",SWITCH(BL62,0.5,$L$22-1,1,$L$22,$L$22+BL62-1),"M/D",SWITCH(BL62,0.5,$L$22-2,1,$L$22-1,$L$22+BL62-2),"M/MD",SWITCH(BL62,0.5,$L$22-3,1,$L$22-2,2,$L$22-1,$L$22+BL62/2-2),"F/F HT",SWITCH(BL62,0.5,$L$28-1,1,$L$28,2,$L$28+1,4,$L$28+2,$L$28+BL62/8+2),"F/M HT",SWITCH(BL62,0.5,$L$28-2,1,$L$28-1,2,$L$28,4,$L$28+1,$L$28+BL62/8+1),"F/D HT",SWITCH(BL62,0.5,$L$28-3,1,$L$28-2,2,$L$28-1,4,$L$28,$L$28+BL62/8),"M/F HT",SWITCH(BL62,0.5,$L$28-1,1,$L$28,$L$28+BL62/2),"M/M HT",SWITCH(BL62,0.5,$L$28-2,1,$L$28-1,$L$28+BL62/2-1),"M/D HT",SWITCH(BL62,0.5,$L$28-3,1,$L$28-2,$L$28+BL62/2-2),"M/MD HT",SWITCH(BL62,0.5,$L$28-4,1,$L$28-3,2,$L$28-2,$L$28+BL62/4-2),"")+(SWITCH(CM62,"A",4,"B",$BF$64,"C","","D",3,"E",1,"G",4,"H",1,"L",0,"M",$AD$92,"S",$BF$66,"T",$AD$132,"U",3,"V",2,"R",1,"")+SWITCH(CN62,"A",4,"B",$BF$64,"C","","D",3,"E",1,"G",4,"H",1,"L",0,"M",$AD$92,"S",$BF$66,"T",$AD$132,"U",3,"V",2,"R",1,"")+SWITCH(CO62,"A",4,"B",$BF$64,"C","","D",3,"E",1,"G",4,"H",1,"L",0,"M",$AD$92,"S",$BF$66,"T",$AD$132,"U",3,"V",2,"R",1,"")) -> 18
E63: =if(BA275<=N50,V50,if(BA275<=N52,V52,if(BA275<=N54,V54,if(BA275<=N56,V56,if(BA275<=N58,V58,1))))) -> #REF! | J63: =if(BA275<=N50,V50,if(BA275<=N52,V52,if(BA275<=N54,V54,if(BA275<=N56,V56,if(BA275<=N58,V58,1))))) -> #REF! | O63: =rounddown($CJ$26/2,0) -> 10 | R63: =rounddown($CJ$28*2/3,0) -> 11 | X63: =ROUNDDOWN($CJ$30/2,0) -> 9
AI64: Aparência | AO64: Comum | BF64: 0 | BL64: 2 | BO64: Eng. Mec. 4 (Mineiração) | CD64: M/D | CJ64: =SWITCH(CD64,"F/F",SWITCH(BL64,0.5,$L$16-1,1,$L$16,2,$L$16+1,4,$L$16+2,$L$16+BL64/8+2),"F/M",SWITCH(BL64,0.5,$L$16-2,1,$L$16-1,2,$L$16,4,$L$16+1,$L$16+BL64/8+1),"F/D",SWITCH(BL64,0.5,$L$16-3,1,$L$16-2,2,$L$16-1,4,$L$16,$L$16+BL64/8),"M/F",SWITCH(BL64,0.5,$L$22,1,$L$22+1,$L$22+BL64),"M/M",SWITCH(BL64,0.5,$L$22-1,1,$L$22,$L$22+BL64-1),"M/D",SWITCH(BL64,0.5,$L$22-2,1,$L$22-1,$L$22+BL64-2),"M/MD",SWITCH(BL64,0.5,$L$22-3,1,$L$22-2,2,$L$22-1,$L$22+BL64/2-2),"F/F HT",SWITCH(BL64,0.5,$L$28-1,1,$L$28,2,$L$28+1,4,$L$28+2,$L$28+BL64/8+2),"F/M HT",SWITCH(BL64,0.5,$L$28-2,1,$L$28-1,2,$L$28,4,$L$28+1,$L$28+BL64/8+1),"F/D HT",SWITCH(BL64,0.5,$L$28-3,1,$L$28-2,2,$L$28-1,4,$L$28,$L$28+BL64/8),"M/F HT",SWITCH(BL64,0.5,$L$28-1,1,$L$28,$L$28+BL64/2),"M/M HT",SWITCH(BL64,0.5,$L$28-2,1,$L$28-1,$L$28+BL64/2-1),"M/D HT",SWITCH(BL64,0.5,$L$28-3,1,$L$28-2,$L$28+BL64/2-2),"M/MD HT",SWITCH(BL64,0.5,$L$28-4,1,$L$28-3,2,$L$28-2,$L$28+BL64/4-2),"")+(SWITCH(CM64,"A",4,"B",$BF$64,"C","","D",3,"E",1,"G",4,"H",1,"L",0,"M",$AD$92,"S",$BF$66,"T",$AD$132,"U",3,"V",2,"R",1,"")+SWITCH(CN64,"A",4,"B",$BF$64,"C","","D",3,"E",1,"G",4,"H",1,"L",0,"M",$AD$92,"S",$BF$66,"T",$AD$132,"U",3,"V",2,"R",1,"")+SWITCH(CO64,"A",4,"B",$BF$64,"C","","D",3,"E",1,"G",4,"H",1,"L",0,"M",$AD$92,"S",$BF$66,"T",$AD$132,"U",3,"V",2,"R",1,"")) -> 20
E66: BAL | J66: GDP | O66: Machado | R66: Briga | AI66: Status | AO66: Mestre Artesão | BF66: =AD100 -> 1 | BL66: 0.5 | BO66: Metalografia | CD66: M/D | CJ66: =SWITCH(CD66,"F/F",SWITCH(BL66,0.5,$L$16-1,1,$L$16,2,$L$16+1,4,$L$16+2,$L$16+BL66/8+2),"F/M",SWITCH(BL66,0.5,$L$16-2,1,$L$16-1,2,$L$16,4,$L$16+1,$L$16+BL66/8+1),"F/D",SWITCH(BL66,0.5,$L$16-3,1,$L$16-2,2,$L$16-1,4,$L$16,$L$16+BL66/8),"M/F",SWITCH(BL66,0.5,$L$22,1,$L$22+1,$L$22+BL66),"M/M",SWITCH(BL66,0.5,$L$22-1,1,$L$22,$L$22+BL66-1),"M/D",SWITCH(BL66,0.5,$L$22-2,1,$L$22-1,$L$22+BL66-2),"M/MD",SWITCH(BL66,0.5,$L$22-3,1,$L$22-2,2,$L$22-1,$L$22+BL66/2-2),"F/F HT",SWITCH(BL66,0.5,$L$28-1,1,$L$28,2,$L$28+1,4,$L$28+2,$L$28+BL66/8+2),"F/M HT",SWITCH(BL66,0.5,$L$28-2,1,$L$28-1,2,$L$28,4,$L$28+1,$L$28+BL66/8+1),"F/D HT",SWITCH(BL66,0.5,$L$28-3,1,$L$28-2,2,$L$28-1,4,$L$28,$L$28+BL66/8),"M/F HT",SWITCH(BL66,0.5,$L$28-1,1,$L$28,$L$28+BL66/2),"M/M HT",SWITCH(BL66,0.5,$L$28-2,1,$L$28-1,$L$28+BL66/2-1),"M/D HT",SWITCH(BL66,0.5,$L$28-3,1,$L$28-2,$L$28+BL66/2-2),"M/MD HT",SWITCH(BL66,0.5,$L$28-4,1,$L$28-3,2,$L$28-2,$L$28+BL66/4-2),"")+(SWITCH(CM66,"A",4,"B",$BF$64,"C","","D",3,"E",1,"G",4,"H",1,"L",0,"M",$AD$92,"S",$BF$66,"T",$AD$132,"U",3,"V",2,"R",1,"")+SWITCH(CN66,"A",4,"B",$BF$64,"C","","D",3,"E",1,"G",4,"H",1,"L",0,"M",$AD$92,"S",$BF$66,"T",$AD$132,"U",3,"V",2,"R",1,"")+SWITCH(CO66,"A",4,"B",$BF$64,"C","","D",3,"E",1,"G",4,"H",1,"L",0,"M",$AD$92,"S",$BF$66,"T",$AD$132,"U",3,"V",2,"R",1,"")) -> 18
F68: DP Total | P68: Proteção | W68: RD Total | AI68: Reputação | AO68: Matador de Titã | BF68: =AD98 -> 1 | BL68: 0.5 | BO68: Prospecção | CD68: M/M | CJ68: =SWITCH(CD68,"F/F",SWITCH(BL68,0.5,$L$16-1,1,$L$16,2,$L$16+1,4,$L$16+2,$L$16+BL68/8+2),"F/M",SWITCH(BL68,0.5,$L$16-2,1,$L$16-1,2,$L$16,4,$L$16+1,$L$16+BL68/8+1),"F/D",SWITCH(BL68,0.5,$L$16-3,1,$L$16-2,2,$L$16-1,4,$L$16,$L$16+BL68/8),"M/F",SWITCH(BL68,0.5,$L$22,1,$L$22+1,$L$22+BL68),"M/M",SWITCH(BL68,0.5,$L$22-1,1,$L$22,$L$22+BL68-1),"M/D",SWITCH(BL68,0.5,$L$22-2,1,$L$22-1,$L$22+BL68-2),"M/MD",SWITCH(BL68,0.5,$L$22-3,1,$L$22-2,2,$L$22-1,$L$22+BL68/2-2),"F/F HT",SWITCH(BL68,0.5,$L$28-1,1,$L$28,2,$L$28+1,4,$L$28+2,$L$28+BL68/8+2),"F/M HT",SWITCH(BL68,0.5,$L$28-2,1,$L$28-1,2,$L$28,4,$L$28+1,$L$28+BL68/8+1),"F/D HT",SWITCH(BL68,0.5,$L$28-3,1,$L$28-2,2,$L$28-1,4,$L$28,$L$28+BL68/8),"M/F HT",SWITCH(BL68,0.5,$L$28-1,1,$L$28,$L$28+BL68/2),"M/M HT",SWITCH(BL68,0.5,$L$28-2,1,$L$28-1,$L$28+BL68/2-1),"M/D HT",SWITCH(BL68,0.5,$L$28-3,1,$L$28-2,$L$28+BL68/2-2),"M/MD HT",SWITCH(BL68,0.5,$L$28-4,1,$L$28-3,2,$L$28-2,$L$28+BL68/4-2),"")+(SWITCH(CM68,"A",4,"B",$BF$64,"C","","D",3,"E",1,"G",4,"H",1,"L",0,"M",$AD$92,"S",$BF$66,"T",$AD$132,"U",3,"V",2,"R",1,"")+SWITCH(CN68,"A",4,"B",$BF$64,"C","","D",3,"E",1,"G",4,"H",1,"L",0,"M",$AD$92,"S",$BF$66,"T",$AD$132,"U",3,"V",2,"R",1,"")+SWITCH(CO68,"A",4,"B",$BF$64,"C","","D",3,"E",1,"G",4,"H",1,"L",0,"M",$AD$92,"S",$BF$66,"T",$AD$132,"U",3,"V",2,"R",1,"")) -> 19
F70: 4 | H70: + | I70: 4 | K70: = | L70: =F70+I70 -> 8 | P70: Cabeça | W70: 6 | Y70: + | Z70: =$AD$112 -> 3 | AB70: = | AC70: =W70+Z70 -> 9 | AI70: S. Dever | AO70: Grupo | BF70: =2 -> 2 | BL70: 0.5 | BO70: CdT: A Forja | CD70: M/F | CJ70: =SWITCH(CD70,"F/F",SWITCH(BL70,0.5,$L$16-1,1,$L$16,2,$L$16+1,4,$L$16+2,$L$16+BL70/8+2),"F/M",SWITCH(BL70,0.5,$L$16-2,1,$L$16-1,2,$L$16,4,$L$16+1,$L$16+BL70/8+1),"F/D",SWITCH(BL70,0.5,$L$16-3,1,$L$16-2,2,$L$16-1,4,$L$16,$L$16+BL70/8),"M/F",SWITCH(BL70,0.5,$L$22,1,$L$22+1,$L$22+BL70),"M/M",SWITCH(BL70,0.5,$L$22-1,1,$L$22,$L$22+BL70-1),"M/D",SWITCH(BL70,0.5,$L$22-2,1,$L$22-1,$L$22+BL70-2),"M/MD",SWITCH(BL70,0.5,$L$22-3,1,$L$22-2,2,$L$22-1,$L$22+BL70/2-2),"F/F HT",SWITCH(BL70,0.5,$L$28-1,1,$L$28,2,$L$28+1,4,$L$28+2,$L$28+BL70/8+2),"F/M HT",SWITCH(BL70,0.5,$L$28-2,1,$L$28-1,2,$L$28,4,$L$28+1,$L$28+BL70/8+1),"F/D HT",SWITCH(BL70,0.5,$L$28-3,1,$L$28-2,2,$L$28-1,4,$L$28,$L$28+BL70/8),"M/F HT",SWITCH(BL70,0.5,$L$28-1,1,$L$28,$L$28+BL70/2),"M/M HT",SWITCH(BL70,0.5,$L$28-2,1,$L$28-1,$L$28+BL70/2-1),"M/D HT",SWITCH(BL70,0.5,$L$28-3,1,$L$28-2,$L$28+BL70/2-2),"M/MD HT",SWITCH(BL70,0.5,$L$28-4,1,$L$28-3,2,$L$28-2,$L$28+BL70/4-2),"")+(SWITCH(CM70,"A",4,"B",$BF$64,"C","","D",3,"E",1,"G",4,"H",1,"L",0,"M",$AD$92,"S",$BF$66,"T",$AD$132,"U",3,"V",2,"R",1,"")+SWITCH(CN70,"A",4,"B",$BF$64,"C","","D",3,"E",1,"G",4,"H",1,"L",0,"M",$AD$92,"S",$BF$66,"T",$AD$132,"U",3,"V",2,"R",1,"")+SWITCH(CO70,"A",4,"B",$BF$64,"C","","D",3,"E",1,"G",4,"H",1,"L",0,"M",$AD$92,"S",$BF$66,"T",$AD$132,"U",3,"V",2,"R",1,"")) -> 20
...

Sheet Página 1 Impressão
E2: O REINO | V2: Nome | AA2: Baldo | BB2: Jogador | BH2: Kauê | BV2: Data de Criação | CF2: 2014
V4: Altura | AA4: 1,36 m | AF4: Peso | AJ4: 91 kg | AO4: Raça | AS4: Anão | AZ4: Reino | BE4: Nog Faldur | BO4: Idade | BV4: Pontos p/ Gastar
V6: Aparência | AC6: Olhos laranjas, cabelo marrom trançado
E8: PLANILHA DE PERSONAGEM
E10: ST | T10: P. Fadiga | Z10: =L10 | AC10: / | AD10: =L10 | BL10: Perícias
T13: P. Mana | Z13: =$L$10 | AC13: / | AD13: =$L$10 | BK13: Custo | BO13: Nome | CC13: Dificuldade | CJ13: NH
BO14: Trovador | CD14: M/M
E16: DX | T16: Vontade | BO16: Caligrafia | CD16: F/M
BO18: Dança | CD18: F/M
BO20: Escultura | CD20: F/M | CM20: D
E22: IQ | T22: Percepção | Z22: =L22 | BO22: Controle da Respiração | CD22: M/MD
BO24: Corrida | CD24: F/D HT
BO26: Machado/Maça | CD26: F/M
E28: HT | T28: P. Vida | AC28: / | BO28: Briga | CD28: F/F
BO30: Escudo | CD30: F/F
BO32: Armeiro 4 | CD32: M/M | CM32: D
E34: Base de Carga | O34: Dano GDP | X34: Dano BAL | BO34: Ferreiro 4 | CD34: M/M | CM34: D
E36: =L10 | BO36: Carpintaria | CD36: M/F | CM36: D
BO38: Culinaria | CD38: M/F | CM38: D
BO40: Joalheiro 4 | CD40: M/D | CM40: D
E41: Velocidade Básica | S41: Deslocamento Básico
BO42: Trabalhos em Couro | CD42: M/F | CM42: D | CP42: $
BO44: Mecanica 4 (Engrenagens) | CD44: M/F | CM44: D | CP44: $
BO46: Ceramica | CD46: M/M | CM46: D | CP46: $
E48: Nível de Carga | R48: Deslocamento | Z48: Esquiva | BO48: Marcenaria | CD48: F/M | CM48: D
E50: Nenhuma (0) = BC | N50: =$E$36 | R50: DB | V50: =$S$43 | Z50: Esquiva | BO50: Destilaria | CD50: M/M | CM50: D
E52: Leve (1) = 2,5xBC | R52: DB-1 | Z52: Esquiva-1 | BO52: Alvenaria | CD52: F/F | CM52: D
E54: Média (2) = 5xBC | R54: DB-2 | Z54: Esquiva-2 | BO54: Comum | CD54: M/M
E56: Pesada (3) = 10xBC | R56: DB-3 | Z56: Esquiva-3 | BO56: Primeiros Socorros | CD56: M/F
E58: M.Pes (4) = 15xBC | R58: DB-4 | Z58: Esquiva-4 | BO58: Naturalista | CD58: M/D
BO60: Geologia 4 | CD60: M/D
E61: Esquiva | O61: Aparar | X61: Bloqueio | AI61: Modificadores de Reação
BO62: História | CD62: M/D
AI64: Aparência | AO64: Comum | BO64: Eng. Mec. 4 (Mineiração) | CD64: M/D
E66: BAL | J66: GDP | O66: Machado | R66: Briga | AI66: Status | AO66: Mestre Artesão | BO66: Metalografia | CD66: M/D
F68: DP Total | P68: Proteção | W68: RD Total | AI68: Reputação | AO68: Matador de Titã | BO68: Prospecção | CD68: M/M
H70: + | K70: = | P70: Cabeça | Y70: + | AB70: = | AI70: S. Dever | AO70: Grupo | BO70: CdT: A Forja | CD70: M/F
H72: + | K72: = | P72: Tronco | Y72: + | AB72: = | BO72: Diplomacia | CD72: M/D
H74: + | K74: = | P74: Braços | Y74: + | AB74: = | BO74: Comércio | CD74: M/M
H76: + | K76: = | P76: Mãos | Y76: + | AB76: = | BO76: Trato Social | CD76: M/F
...

Sheet Página 2 Impressão
F5: Armas de Longo Alcance | BL5: Anotações do Personagem
F7: Arma | T7: Dano | Y7: Prec | AC7: 1/2 D | AG7: Max | AJ7: Tiros | AN7: CdT | AQ7: TR | AT7: RCO | AW7: ST | AZ7: Notas
T8: =if(isblank(F8),"",Concatenate(#REF!,if((#REF!)<>0,concatenate("+",#REF!),""))) | BL8: =CONCATENATE("Salario: $ Peças de Ouro") -> Salario: $ Peças de Ouro
T10: =if(isblank(F10),"",Concatenate(#REF!,if((#REF!)<>0,concatenate("+",#REF!),""))) | BL10: Obsessão: Achar e adquirir as lendarias runas
T12: =if(isblank(F12),"",Concatenate(#REF!,if((#REF!)<>0,concatenate("+",#REF!),""))) | BL12: de Thuril. Tais runas dão bonus de +5 ao NH, são
T14: =if(isblank(F14),"",Concatenate(#REF!,if((#REF!)<>0,concatenate("+",#REF!),""))) | BL14: indestrutiveis e, se a magia de runas for
E16: =if(isblank(F16),"",Concatenate(#REF!,if((#REF!)<>0,concatenate("+",#REF!),""))) | BL16: executada somente com runas de Thuril. o custo
F17: Armas de Combate Corpo a Corpo
BL18: inerente de +2 de energia é eliminado. Existem
F19: Arma | T19: Qualidade | AA19: GDP | AG19: Tipo | AM19: BAL | AS19: Tipo | AY19: Notas
F20: Machado | T20: Normal | AG20: Contusão | AS20: Corte | BL20: 25 runas, 1 para cada palavra de poder.
F22: Machadinha | T22: Superior | AG22: Contusão | AS22: Corte | BL22: *Fabricação Própria: -30% no custo
F24: Escudo Grande | T24: Normal | AA24: =if(isblank(F24),"",Concatenate($O$36,if(($T$36)<>0,concatenate("+",$T$36),""))) | AG24: Contusão | BL24: Descrição do assassino da Ana
F26: Machado da caça mag | T26: Altíssima | AA26: =if(isblank(F26),"",Concatenate($O$36,if(($T$36)<>0,concatenate("+",$T$36),""))) | AG26: Contusão | AS26: corte | AY26: 1 acerto -1RD -1DP | BL26: tatuagem de inteligência
T28: -- | AA28: =if(isblank(F28),"",TEXTJOIN("",false,#REF!,#REF!+2)) | AM28: =if(isblank(F28),"",Concatenate(#REF!,if((#REF!+2)<>0,concatenate("+",#REF!+2),"")))
F30: -- | BL30: destilador de essência
F31: Inventário | AI31: Itens mágicos
F34: Item | X34: Peso | AB34: Custo | AI34: Item | AV34: Peso | AZ34: Custo | BE34: Mana
F37: cerveja azul
F39: cerveja vermelha
F41: gema de mana (25)
F43: braç visão noturna
F45: braç moldar trevas
F47: pó de fada
F49: escamas da aberração
F51: geleia de fada
F53: corrente de mytril
F55: pedra p/ amolar
F57: pedra estranha
F59: raspa de casca de dríade
... F73: poção pérola liquida
BL107: Moedas de Ouro | BU107: Moedas de Prata | CD107: Moedas de Cobre
BK114: $ | BU114: $ | CD114: $
AI120: Armadura | BL120: Resumo de Pontos
BL123: Atributos
BL125: Vantagens
BL127: Desvantagens
BL129: Raça
BL131: Peculiaridades
BL133: Perícias
...

Sheet Grimório
F1: Grimório de Magias
F3: Custo | I3: Nome da Magia | AK3: NH | AN3: Pág. | AQ3: Classe | AZ3: Duração | BI3: Custo | BO3: Custo p/ manter | BV3: T. O. | CB3: Observações
F4: 20 | I4: Ativação de Runas | AH4: MD | AK4: =IF(AH4="D", switch(F4,"","",1,Ficha!$L$22+Ficha!$AD$92+Ficha!$AD$90-2,2,Ficha!$L$22+Ficha!$AD$92+Ficha!$AD$90-1,Ficha!$L$22+Ficha!$AD$92+Ficha!$AD$90+(F4/2)-2),IF(AH4="MD",switch(F4,"","",1,Ficha!$L$22+Ficha!$AD$92+Ficha!$AD$90-3,2,Ficha!$L$22+Ficha!$AD$92+Ficha!$AD$90-2,2,Ficha!$L$22+Ficha!$AD$92+Ficha!$AD$90-2-1,Ficha!$L$22+Ficha!$AD$92+Ficha!$AD$90+(F4/4)-2))) -> 25 | AN4: 82
F6: 8 | I6: Runa: Controlar | AH6: D | AK6: =switch(AH6,"F",switch(F6,"","",0.5,Ficha!$L$22,Ficha!$L$22+F6),"M",switch(F6,"","",0.5,Ficha!$L$22-1,Ficha!$L$22+F6-1),"D",switch(F6,"","",0.5,Ficha!$L$22-2,Ficha!$L$22+F6-2),"") -> 26 | AN6: 81 | AQ6: Usos: | AZ6: Controlar | BM6: Atar
F8: 5 | I8: Runa: Curar | AH8: D | AK8: =switch(AH8,"F",switch(F8,"","",0.5,Ficha!$L$22,Ficha!$L$22+F8),"M",switch(F8,"","",0.5,Ficha!$L$22-1,Ficha!$L$22+F8-1),"D",switch(F8,"","",0.5,Ficha!$L$22-2,Ficha!$L$22+F8-2),"") -> 23 | AN8: 81 | AQ8: Usos: | AZ8: Curar | BM8: Fertilidade
F10: 3 | I10: Runa: Fortalecer | AH10: M | AK10: =switch(AH10,"F",switch(F10,"","",0.5,Ficha!$L$22,Ficha!$L$22+F10),"M",switch(F10,"","",0.5,Ficha!$L$22-1,Ficha!$L$22+F10-1),"D",switch(F10,"","",0.5,Ficha!$L$22-2,Ficha!$L$22+F10-2),"") -> 22 | AN10: 81 | AQ10: Usos: | AZ10: Fortalecer | BM10: Restaurar
F12: 3 | I12: Runa: Deslocar | AH12: M | AK12: =switch(AH12,"F",switch(F12,"","",0.5,Ficha!$L$22,Ficha!$L$22+F12),"M",switch(F12,"","",0.5,Ficha!$L$22-1,Ficha!$L$22+F12-1),"D",switch(F12,"","",0.5,Ficha!$L$22-2,Ficha!$L$22+F12-2),"") -> 22 | AN12: 81 | AQ12: Usos: | AZ12: Deslocar | BM12: Viajar
F14: 4 | I14: Runa: Proteger | AH14: M | AK14: =switch(AH14,"F",switch(F14,"","",0.5,Ficha!$L$22,Ficha!$L$22+F14),"M",switch(F14,"","",0.5,Ficha!$L$22-1,Ficha!$L$22+F14-1),"D",switch(F14,"","",0.5,Ficha!$L$22-2,Ficha!$L$22+F14-2),"") -> 23 | AN14: 81 | AQ14: Usos: | AZ14: Proteger | BM14: Guardar
F16: 3 | I16: Runa: Terra | AH16: M | AK16: =switch(AH16,"F",switch(F16,"","",0.5,Ficha!$L$22,Ficha!$L$22+F16),"M",switch(F16,"","",0.5,Ficha!$L$22-1,Ficha!$L$22+F16-1),"D",switch(F16,"","",0.5,Ficha!$L$22-2,Ficha!$L$22+F16-2),"") -> 22 | AN16: 81 | AQ16: Usos: | AZ16: Terra | BM16: Metal
F18: 4 | I18: Runa: Magia | AH18: D | AK18: =switch(AH18,"F",switch(F18,"","",0.5,Ficha!$L$22,Ficha!$L$22+F18),"M",switch(F18,"","",0.5,Ficha!$L$22-1,Ficha!$L$22+F18-1),"D",switch(F18,"","",0.5,Ficha!$L$22-2,Ficha!$L$22+F18-2),"") -> 22 | AN18: 81 | AQ18: Usos: | AZ18: Magia | BM18: Destino
F20: 5 | I20: Runa: Corpo (Homem) | AH20: D | AK20: =switch(AH20,"F",switch(F20,"","",0.5,Ficha!$L$22,Ficha!$L$22+F20),"M",switch(F20,"","",0.5,Ficha!$L$22-1,Ficha!$L$22+F20-1),"D",switch(F20,"","",0.5,Ficha!$L$22-2,Ficha!$L$22+F20-2),"") -> 23 | AN20: 81 | AQ20: Usos: | AZ20: Corpo (Homem) | BM20: Homem | BZ20: Ser Humano
F22: 3 | I22: Runa: Fogo | AH22: M | AK22: =switch(AH22,"F",switch(F22,"","",0.5,Ficha!$L$22,Ficha!$L$22+F22),"M",switch(F22,"","",0.5,Ficha!$L$22-1,Ficha!$L$22+F22-1),"D",switch(F22,"","",0.5,Ficha!$L$22-2,Ficha!$L$22+F22-2),"") -> 22 | AN22: 81 | AQ22: Usos: | AZ22: Fogo | BM22: Calor | BZ22: Frio
F24: 2 | I24: Runa: Alimento | AH24: F | AK24: =switch(AH24,"F",switch(F24,"","",0.5,Ficha!$L$22,Ficha!$L$22+F24),"M",switch(F24,"","",0.5,Ficha!$L$22-1,Ficha!$L$22+F24-1),"D",switch(F24,"","",0.5,Ficha!$L$22-2,Ficha!$L$22+F24-2),"") -> 22 | AN24: 81 | AQ24: Usos: | AZ24: Oferenda | BM24: Oferenda
F26: 3 | I26: Runa: Plantas | AH26: M | AK26: =switch(AH26,"F",switch(F26,"","",0.5,Ficha!$L$22,Ficha!$L$22+F26),"M",switch(F26,"","",0.5,Ficha!$L$22-1,Ficha!$L$22+F26-1),"D",switch(F26,"","",0.5,Ficha!$L$22-2,Ficha!$L$22+F26-2),"") -> 22 | AN26: 81 | AQ26: Usos: | AZ26: Alimentos
F28: 3 | I28: Runa: Romper | AH28: M | AK28: =switch(AH28,"F",switch(F28,"","",0.5,Ficha!$L$22,Ficha!$L$22+F28),"M",switch(F28,"","",0.5,Ficha!$L$22-1,Ficha!$L$22+F28-1),"D",switch(F28,"","",0.5,Ficha!$L$22-2,Ficha!$L$22+F28-2),"") -> 22 | AN28: 81 | AQ28: Usos: | AZ28: Plantas | BM28: Enfraquecer | BZ28: Ferir
F30: 5 | I30: Runa: Transformar | AH30: D | AK30: =switch(AH30,"F",switch(F30,"","",0.5,Ficha!$L$22,Ficha!$L$22+F30),"M",switch(F30,"","",0.5,Ficha!$L$22-1,Ficha!$L$22+F30-1),"D",switch(F30,"","",0.5,Ficha!$L$22-2,Ficha!$L$22+F30-2),"") -> 23 | AN30: 81 | AQ30: Usos: | AZ30: Transformar | BM30: Passagem
F32: 5 | I32: Runa: Criar | AH32: D | AK32: =switch(AH32,"F",switch(F32,"","",0.5,Ficha!$L$22,Ficha!$L$22+F32),"M",switch(F32,"","",0.5,Ficha!$L$22-1,Ficha!$L$22+F32-1),"D",switch(F32,"","",0.5,Ficha!$L$22-2,Ficha!$L$22+F32-2),"") -> 23 | AN32: 81 | AQ32: Usos: | AZ32: Criar
F34: 5 | I34: Runa: Presentir | AH34: D | AK34: =switch(AH34,"F",switch(F34,"","",0.5,Ficha!$L$22,Ficha!$L$22+F34),"M",switch(F34,"","",0.5,Ficha!$L$22-1,Ficha!$L$22+F34-1),"D",switch(F34,"","",0.5,Ficha!$L$22-2,Ficha!$L$22+F34-2),"") -> 23 | AN34: 81 | AQ34: Usos: | AZ34: Presentir | BM34: Conhecimento | BZ34: Denominação
F36: 4 | I36: Runa: Comunicar | AH36: M | AK36: =switch(AH36,"F",switch(F36,"","",0.5,Ficha!$L$22,Ficha!$L$22+F36),"M",switch(F36,"","",0.5,Ficha!$L$22-1,Ficha!$L$22+F36-1),"D",switch(F36,"","",0.5,Ficha!$L$22-2,Ficha!$L$22+F36-2),"") -> 23 | AN36: 81 | AQ36: Usos: | AZ36: Comunicar | BM36: Separar
F38: 1 | I38: Runa: Alertar | AH38: M | AK38: =switch(AH38,"F",switch(F38,"","",0.5,Ficha!$L$22,Ficha!$L$22+F38),"M",switch(F38,"","",0.5,Ficha!$L$22-1,Ficha!$L$22+F38-1),"D",switch(F38,"","",0.5,Ficha!$L$22-2,Ficha!$L$22+F38-2),"") -> 20 | AN38: 81 | AQ38: Usos: | AZ38: Alertar
F40: 5 | I40: Runa: Animal | AH40: D | AK40: =switch(AH40,"F",switch(F40,"","",0.5,Ficha!$L$22,Ficha!$L$22+F40),"M",switch(F40,"","",0.5,Ficha!$L$22-1,Ficha!$L$22+F40-1),"D",switch(F40,"","",0.5,Ficha!$L$22-2,Ficha!$L$22+F40-2),"") -> 23 | AN40: 81 | AQ40: Usos: | AZ40: Animal | BM40: Prosperidade
F42: 5 | I42: Runa: Mente | AH42: D | AK42: =switch(AH42,"F",switch(F42,"","",0.5,Ficha!$L$22,Ficha!$L$22+F42),"M",switch(F42,"","",0.5,Ficha!$L$22-1,Ficha!$L$22+F42-1),"D",switch(F42,"","",0.5,Ficha!$L$22-2,Ficha!$L$22+F42-2),"") -> 23 | AN42: 81 | AQ42: Usos: | AZ42: Mente | BM42: Emoções
F44: 4 | I44: Runa: Alma | AH44: D | AK44: =switch(AH44,"F",switch(F44,"","",0.5,Ficha!$L$22,Ficha!$L$22+F44),"M",switch(F44,"","",0.5,Ficha!$L$22-1,Ficha!$L$22+F44-1),"D",switch(F44,"","",0.5,Ficha!$L$22-2,Ficha!$L$22+F44-2),"") -> 22 | AN44: 81 | AQ44: Usos: | AZ44: Alma | BM44: Necromancia | BZ44: Mortos Vivos T
F46: 4 | I46: Runa: Ar | AH46: M | AK46: =switch(AH46,"F",switch(F46,"","",0.5,Ficha!$L$22,Ficha!$L$22+F46),"M",switch(F46,"","",0.5,Ficha!$L$22-1,Ficha!$L$22+F46-1),"D",switch(F46,"","",0.5,Ficha!$L$22-2,Ficha!$L$22+F46-2),"") -> 23 | AN46: 81 | AQ46: Usos: | AZ46: Ar | BM46: Raio
F48: 4 | I48: Runa: Água | AH48: M | AK48: =switch(AH48,"F",switch(F48,"","",0.5,Ficha!$L$22,Ficha!$L$22+F48),"M",switch(F48,"","",0.5,Ficha!$L$22-1,Ficha!$L$22+F48-1),"D",switch(F48,"","",0.5,Ficha!$L$22-2,Ficha!$L$22+F48-2),"") -> 23 | AN48: 81 | AQ48: Usos: | AZ48: Água | BM48: Gelo
F50: 3 | I50: Runa: Ilusão | AH50: M | AK50: =switch(AH50,"F",switch(F50,"","",0.5,Ficha!$L$22,Ficha!$L$22+F50),"M",switch(F50,"","",0.5,Ficha!$L$22-1,Ficha!$L$22+F50-1),"D",switch(F50,"","",0.5,Ficha!$L$22-2,Ficha!$L$22+F50-2),"") -> 22 | AN50: 81 | AQ50: Usos: | AZ50: Ilusão | BM50: Mistério
F52: 3 | I52: Runa: Luz | AH52: M | AK52: =switch(AH52,"F",switch(F52,"","",0.5,Ficha!$L$22,Ficha!$L$22+F52),"M",switch(F52,"","",0.5,Ficha!$L$22-1,Ficha!$L$22+F52-1),"D",switch(F52,"","",0.5,Ficha!$L$22-2,Ficha!$L$22+F52-2),"") -> 22 | AN52: 81 | AQ52: Usos: | AZ52: Luz | BM52: Trevas
F54: 1 | I54: Runa: Som | AH54: F | AK54: =switch(AH54,"F",switch(F54,"","",0.5,Ficha!$L$22,Ficha!$L$22+F54),"M",switch(F54,"","",0.5,Ficha!$L$22-1,Ficha!$L$22+F54-1),"D",switch(F54,"","",0.5,Ficha!$L$22-2,Ficha!$L$22+F54-2),"") -> 21 | AN54: 81 | AQ54: Usos: | AZ54: Som | BM54: Sinais
AH56: D | AK56: =IF(AH56="D", switch(F56,"","",1,Ficha!$L$22+Ficha!$AD$128-2,2,Ficha!$L$22+Ficha!$AD$128-1,Ficha!$L$22+Ficha!$AD$128+(F56/2)-2),IF(AH56="MD",switch(F56,"","",1,Ficha!$L$22+Ficha!$AD$128-3,2,Ficha!$L$22+Ficha!$AD$128-2,2,Ficha!$L$22+Ficha!$AD$128-2-1,Ficha!$L$22+Ficha!$AD$128+(F56/4)-2)))
AH58: D | AK58: =IF(AH58="D", switch(F58,"","",1,Ficha!$L$22+Ficha!$AD$128-2,2,Ficha!$L$22+Ficha!$AD$128-1,Ficha!$L$22+Ficha!$AD$128+(F58/2)-2),IF(AH58="MD",switch(F58,"","",1,Ficha!$L$22+Ficha!$AD$128-3,2,Ficha!$L$22+Ficha!$AD$128-2,2,Ficha!$L$22+Ficha!$AD$128-2-1,Ficha!$L$22+Ficha!$AD$128+(F58/4)-2)))
AH60: D | AK60: =IF(AH60="D", switch(F60,"","",1,Ficha!$L$22+Ficha!$AD$128-2,2,Ficha!$L$22+Ficha!$AD$128-1,Ficha!$L$22+Ficha!$AD$128+(F60/2)-2),IF(AH60="MD",switch(F60,"","",1,Ficha!$L$22+Ficha!$AD$128-3,2,Ficha!$L$22+Ficha!$AD$128-2,2,Ficha!$L$22+Ficha!$AD$128-2-1,Ficha!$L$22+Ficha!$AD$128+(F60/4)-2)))
AH62: D | AK62: =IF(AH62="D", switch(F62,"","",1,Ficha!$L$22+Ficha!$AD$128-2,2,Ficha!$L$22+Ficha!$AD$128-1,Ficha!$L$22+Ficha!$AD$128+(F62/2)-2),IF(AH62="MD",switch(F62,"","",1,Ficha!$L$22+Ficha!$AD$128-3,2,Ficha!$L$22+Ficha!$AD$128-2,2,Ficha!$L$22+Ficha!$AD$128-2-1,Ficha!$L$22+Ficha!$AD$128+(F62/4)-2)))
AH64: D | AK64: =IF(AH64="D", switch(F64,"","",1,Ficha!$L$22+Ficha!$AD$128-2,2,Ficha!$L$22+Ficha!$AD$128-1,Ficha!$L$22+Ficha!$AD$128+(F64/2)-2),IF(AH64="MD",switch(F64,"","",1,Ficha!$L$22+Ficha!$AD$128-3,2,Ficha!$L$22+Ficha!$AD$128-2,2,Ficha!$L$22+Ficha!$AD$128-2-1,Ficha!$L$22+Ficha!$AD$128+(F64/4)-2)))
AH66: D | AK66: =IF(AH66="D", switch(F66,"","",1,Ficha!$L$22+Ficha!$AD$128-2,2,Ficha!$L$22+Ficha!$AD$128-1,Ficha!$L$22+Ficha!$AD$128+(F66/2)-2),IF(AH66="MD",switch(F66,"","",1,Ficha!$L$22+Ficha!$AD$128-3,2,Ficha!$L$22+Ficha!$AD$128-2,2,Ficha!$L$22+Ficha!$AD$128-2-1,Ficha!$L$22+Ficha!$AD$128+(F66/4)-2)))
AH68: D | AK68: =IF(AH68="D", switch(F68,"","",1,Ficha!$L$22+Ficha!$AD$128-2,2,Ficha!$L$22+Ficha!$AD$128-1,Ficha!$L$22+Ficha!$AD$128+(F68/2)-2),IF(AH68="MD",switch(F68,"","",1,Ficha!$L$22+Ficha!$AD$128-3,2,Ficha!$L$22+Ficha!$AD$128-2,2,Ficha!$L$22+Ficha!$AD$128-2-1,Ficha!$L$22+Ficha!$AD$128+(F68/4)-2)))
AH70: D | AK70: =IF(AH70="D", switch(F70,"","",1,Ficha!$L$22+Ficha!$AD$128-2,2,Ficha!$L$22+Ficha!$AD$128-1,Ficha!$L$22+Ficha!$AD$128+(F70/2)-2),IF(AH70="MD",switch(F70,"","",1,Ficha!$L$22+Ficha!$AD$128-3,2,Ficha!$L$22+Ficha!$AD$128-2,2,Ficha!$L$22+Ficha!$AD$128-2-1,Ficha!$L$22+Ficha!$AD$128+(F70/4)-2)))
AH72: D | AK72: =IF(AH72="D", switch(F72,"","",1,Ficha!$L$22+Ficha!$AD$128-2,2,Ficha!$L$22+Ficha!$AD$128-1,Ficha!$L$22+Ficha!$AD$128+(F72/2)-2),IF(AH72="MD",switch(F72,"","",1,Ficha!$L$22+Ficha!$AD$128-3,2,Ficha!$L$22+Ficha!$AD$128-2,2,Ficha!$L$22+Ficha!$AD$128-2-1,Ficha!$L$22+Ficha!$AD$128+(F72/4)-2)))
